[2019-06-13 15:45:34 +0800] [329] [DEBUG] Current configuration:
  config: config.py
  bind: ['127.0.0.1:5000']
  backlog: 2048
  workers: 4
  worker_class: gevent
  threads: 1
  worker_connections: 1000
  max_requests: 0
  max_requests_jitter: 0
  timeout: 30
  graceful_timeout: 30
  keepalive: 2
  limit_request_line: 4094
  limit_request_fields: 100
  limit_request_field_size: 8190
  reload: False
  reload_engine: auto
  reload_extra_files: []
  spew: False
  check_config: False
  preload_app: False
  sendfile: None
  reuse_port: False
  chdir: /home/cl811/work/19spring-courses/wsm/proj/ZDBK
  daemon: True
  raw_env: []
  pidfile: log/gunicorn.pid
  worker_tmp_dir: None
  user: 1000
  group: 1000
  umask: 0
  initgroups: False
  tmp_upload_dir: None
  secure_scheme_headers: {'X-FORWARDED-PROTOCOL': 'ssl', 'X-FORWARDED-PROTO': 'https', 'X-FORWARDED-SSL': 'on'}
  forwarded_allow_ips: ['127.0.0.1']
  accesslog: log/access.log
  disable_redirect_access_to_syslog: False
  access_log_format: %(h)s %(l)s %(u)s %(t)s "%(r)s" %(s)s %(b)s "%(f)s" "%(a)s"
  errorlog: log/debug.log
  loglevel: debug
  capture_output: False
  logger_class: gunicorn.glogging.Logger
  logconfig: None
  logconfig_dict: {}
  syslog_addr: udp://localhost:514
  syslog: False
  syslog_prefix: None
  syslog_facility: user
  enable_stdio_inheritance: False
  statsd_host: None
  statsd_prefix: 
  proc_name: None
  default_proc_name: run:app
  pythonpath: None
  paste: None
  on_starting: <function OnStarting.on_starting at 0x7f981611a378>
  on_reload: <function OnReload.on_reload at 0x7f981611a488>
  when_ready: <function WhenReady.when_ready at 0x7f981611a598>
  pre_fork: <function Prefork.pre_fork at 0x7f981611a6a8>
  post_fork: <function Postfork.post_fork at 0x7f981611a7b8>
  post_worker_init: <function PostWorkerInit.post_worker_init at 0x7f981611a8c8>
  worker_int: <function WorkerInt.worker_int at 0x7f981611a9d8>
  worker_abort: <function WorkerAbort.worker_abort at 0x7f981611aae8>
  pre_exec: <function PreExec.pre_exec at 0x7f981611abf8>
  pre_request: <function PreRequest.pre_request at 0x7f981611ad08>
  post_request: <function PostRequest.post_request at 0x7f981611ad90>
  child_exit: <function ChildExit.child_exit at 0x7f981611aea0>
  worker_exit: <function WorkerExit.worker_exit at 0x7f9816138048>
  nworkers_changed: <function NumWorkersChanged.nworkers_changed at 0x7f9816138158>
  on_exit: <function OnExit.on_exit at 0x7f9816138268>
  proxy_protocol: False
  proxy_allow_ips: ['127.0.0.1']
  keyfile: None
  certfile: None
  ssl_version: 2
  cert_reqs: 0
  ca_certs: None
  suppress_ragged_eofs: True
  do_handshake_on_connect: False
  ciphers: TLSv1
  raw_paste_global_conf: []
[2019-06-13 15:45:34 +0800] [329] [INFO] Starting gunicorn 19.9.0
[2019-06-13 15:45:34 +0800] [329] [DEBUG] Arbiter booted
[2019-06-13 15:45:34 +0800] [329] [INFO] Listening at: http://127.0.0.1:5000 (329)
[2019-06-13 15:45:34 +0800] [329] [INFO] Using worker: gevent
[2019-06-13 15:45:34 +0800] [343] [INFO] Booting worker with pid: 343
[2019-06-13 15:45:34 +0800] [355] [INFO] Booting worker with pid: 355
[2019-06-13 15:45:34 +0800] [357] [INFO] Booting worker with pid: 357
[2019-06-13 15:45:34 +0800] [359] [INFO] Booting worker with pid: 359
[2019-06-13 15:45:34 +0800] [343] [ERROR] Exception in worker process
Traceback (most recent call last):
  File "/home/cl811/tools/miniconda3/envs/myenv/lib/python3.6/site-packages/gunicorn/arbiter.py", line 583, in spawn_worker
    worker.init_process()
  File "/home/cl811/tools/miniconda3/envs/myenv/lib/python3.6/site-packages/gunicorn/workers/ggevent.py", line 203, in init_process
    super(GeventWorker, self).init_process()
  File "/home/cl811/tools/miniconda3/envs/myenv/lib/python3.6/site-packages/gunicorn/workers/base.py", line 129, in init_process
    self.load_wsgi()
  File "/home/cl811/tools/miniconda3/envs/myenv/lib/python3.6/site-packages/gunicorn/workers/base.py", line 138, in load_wsgi
    self.wsgi = self.app.wsgi()
  File "/home/cl811/tools/miniconda3/envs/myenv/lib/python3.6/site-packages/gunicorn/app/base.py", line 67, in wsgi
    self.callable = self.load()
  File "/home/cl811/tools/miniconda3/envs/myenv/lib/python3.6/site-packages/gunicorn/app/wsgiapp.py", line 52, in load
    return self.load_wsgiapp()
  File "/home/cl811/tools/miniconda3/envs/myenv/lib/python3.6/site-packages/gunicorn/app/wsgiapp.py", line 41, in load_wsgiapp
    return util.import_app(self.app_uri)
  File "/home/cl811/tools/miniconda3/envs/myenv/lib/python3.6/site-packages/gunicorn/util.py", line 350, in import_app
    __import__(module)
  File "/home/cl811/work/19spring-courses/wsm/proj/ZDBK/run.py", line 3, in <module>
    app.run()
  File "/home/cl811/tools/miniconda3/envs/myenv/lib/python3.6/site-packages/flask/app.py", line 944, in run
    run_simple(host, port, self, **options)
  File "/home/cl811/tools/miniconda3/envs/myenv/lib/python3.6/site-packages/werkzeug/serving.py", line 987, in run_simple
    s.bind(server_address)
OSError: [Errno 98] Address already in use
[2019-06-13 15:45:34 +0800] [343] [INFO] Worker exiting (pid: 343)
[2019-06-13 15:45:34 +0800] [329] [DEBUG] 4 workers
[2019-06-13 15:45:34 +0800] [355] [ERROR] Exception in worker process
Traceback (most recent call last):
  File "/home/cl811/tools/miniconda3/envs/myenv/lib/python3.6/site-packages/gunicorn/arbiter.py", line 583, in spawn_worker
    worker.init_process()
  File "/home/cl811/tools/miniconda3/envs/myenv/lib/python3.6/site-packages/gunicorn/workers/ggevent.py", line 203, in init_process
    super(GeventWorker, self).init_process()
  File "/home/cl811/tools/miniconda3/envs/myenv/lib/python3.6/site-packages/gunicorn/workers/base.py", line 129, in init_process
    self.load_wsgi()
  File "/home/cl811/tools/miniconda3/envs/myenv/lib/python3.6/site-packages/gunicorn/workers/base.py", line 138, in load_wsgi
    self.wsgi = self.app.wsgi()
  File "/home/cl811/tools/miniconda3/envs/myenv/lib/python3.6/site-packages/gunicorn/app/base.py", line 67, in wsgi
    self.callable = self.load()
  File "/home/cl811/tools/miniconda3/envs/myenv/lib/python3.6/site-packages/gunicorn/app/wsgiapp.py", line 52, in load
    return self.load_wsgiapp()
  File "/home/cl811/tools/miniconda3/envs/myenv/lib/python3.6/site-packages/gunicorn/app/wsgiapp.py", line 41, in load_wsgiapp
    return util.import_app(self.app_uri)
  File "/home/cl811/tools/miniconda3/envs/myenv/lib/python3.6/site-packages/gunicorn/util.py", line 350, in import_app
    __import__(module)
  File "/home/cl811/work/19spring-courses/wsm/proj/ZDBK/run.py", line 3, in <module>
    app.run()
  File "/home/cl811/tools/miniconda3/envs/myenv/lib/python3.6/site-packages/flask/app.py", line 944, in run
    run_simple(host, port, self, **options)
  File "/home/cl811/tools/miniconda3/envs/myenv/lib/python3.6/site-packages/werkzeug/serving.py", line 987, in run_simple
    s.bind(server_address)
OSError: [Errno 98] Address already in use
[2019-06-13 15:45:34 +0800] [355] [INFO] Worker exiting (pid: 355)
[2019-06-13 15:45:34 +0800] [357] [ERROR] Exception in worker process
Traceback (most recent call last):
  File "/home/cl811/tools/miniconda3/envs/myenv/lib/python3.6/site-packages/gunicorn/arbiter.py", line 583, in spawn_worker
    worker.init_process()
  File "/home/cl811/tools/miniconda3/envs/myenv/lib/python3.6/site-packages/gunicorn/workers/ggevent.py", line 203, in init_process
    super(GeventWorker, self).init_process()
  File "/home/cl811/tools/miniconda3/envs/myenv/lib/python3.6/site-packages/gunicorn/workers/base.py", line 129, in init_process
    self.load_wsgi()
  File "/home/cl811/tools/miniconda3/envs/myenv/lib/python3.6/site-packages/gunicorn/workers/base.py", line 138, in load_wsgi
    self.wsgi = self.app.wsgi()
  File "/home/cl811/tools/miniconda3/envs/myenv/lib/python3.6/site-packages/gunicorn/app/base.py", line 67, in wsgi
    self.callable = self.load()
  File "/home/cl811/tools/miniconda3/envs/myenv/lib/python3.6/site-packages/gunicorn/app/wsgiapp.py", line 52, in load
    return self.load_wsgiapp()
  File "/home/cl811/tools/miniconda3/envs/myenv/lib/python3.6/site-packages/gunicorn/app/wsgiapp.py", line 41, in load_wsgiapp
    return util.import_app(self.app_uri)
  File "/home/cl811/tools/miniconda3/envs/myenv/lib/python3.6/site-packages/gunicorn/util.py", line 350, in import_app
    __import__(module)
  File "/home/cl811/work/19spring-courses/wsm/proj/ZDBK/run.py", line 3, in <module>
    app.run()
  File "/home/cl811/tools/miniconda3/envs/myenv/lib/python3.6/site-packages/flask/app.py", line 944, in run
    run_simple(host, port, self, **options)
  File "/home/cl811/tools/miniconda3/envs/myenv/lib/python3.6/site-packages/werkzeug/serving.py", line 987, in run_simple
    s.bind(server_address)
OSError: [Errno 98] Address already in use
[2019-06-13 15:45:34 +0800] [357] [INFO] Worker exiting (pid: 357)
[2019-06-13 15:45:34 +0800] [359] [ERROR] Exception in worker process
Traceback (most recent call last):
  File "/home/cl811/tools/miniconda3/envs/myenv/lib/python3.6/site-packages/gunicorn/arbiter.py", line 583, in spawn_worker
    worker.init_process()
  File "/home/cl811/tools/miniconda3/envs/myenv/lib/python3.6/site-packages/gunicorn/workers/ggevent.py", line 203, in init_process
    super(GeventWorker, self).init_process()
  File "/home/cl811/tools/miniconda3/envs/myenv/lib/python3.6/site-packages/gunicorn/workers/base.py", line 129, in init_process
    self.load_wsgi()
  File "/home/cl811/tools/miniconda3/envs/myenv/lib/python3.6/site-packages/gunicorn/workers/base.py", line 138, in load_wsgi
    self.wsgi = self.app.wsgi()
  File "/home/cl811/tools/miniconda3/envs/myenv/lib/python3.6/site-packages/gunicorn/app/base.py", line 67, in wsgi
    self.callable = self.load()
  File "/home/cl811/tools/miniconda3/envs/myenv/lib/python3.6/site-packages/gunicorn/app/wsgiapp.py", line 52, in load
    return self.load_wsgiapp()
  File "/home/cl811/tools/miniconda3/envs/myenv/lib/python3.6/site-packages/gunicorn/app/wsgiapp.py", line 41, in load_wsgiapp
    return util.import_app(self.app_uri)
  File "/home/cl811/tools/miniconda3/envs/myenv/lib/python3.6/site-packages/gunicorn/util.py", line 350, in import_app
    __import__(module)
  File "/home/cl811/work/19spring-courses/wsm/proj/ZDBK/run.py", line 3, in <module>
    app.run()
  File "/home/cl811/tools/miniconda3/envs/myenv/lib/python3.6/site-packages/flask/app.py", line 944, in run
    run_simple(host, port, self, **options)
  File "/home/cl811/tools/miniconda3/envs/myenv/lib/python3.6/site-packages/werkzeug/serving.py", line 987, in run_simple
    s.bind(server_address)
OSError: [Errno 98] Address already in use
[2019-06-13 15:45:34 +0800] [359] [INFO] Worker exiting (pid: 359)
[2019-06-13 15:46:04 +0800] [329] [CRITICAL] WORKER TIMEOUT (pid:343)
[2019-06-13 15:46:04 +0800] [329] [CRITICAL] WORKER TIMEOUT (pid:355)
[2019-06-13 15:46:04 +0800] [329] [CRITICAL] WORKER TIMEOUT (pid:357)
[2019-06-13 15:46:04 +0800] [329] [CRITICAL] WORKER TIMEOUT (pid:359)
[2019-06-13 15:46:04 +0800] [445] [INFO] Booting worker with pid: 445
[2019-06-13 15:46:04 +0800] [447] [INFO] Booting worker with pid: 447
[2019-06-13 15:46:04 +0800] [449] [INFO] Booting worker with pid: 449
[2019-06-13 15:46:04 +0800] [450] [INFO] Booting worker with pid: 450
[2019-06-13 15:46:05 +0800] [445] [ERROR] Exception in worker process
Traceback (most recent call last):
  File "/home/cl811/tools/miniconda3/envs/myenv/lib/python3.6/site-packages/gunicorn/arbiter.py", line 583, in spawn_worker
    worker.init_process()
  File "/home/cl811/tools/miniconda3/envs/myenv/lib/python3.6/site-packages/gunicorn/workers/ggevent.py", line 203, in init_process
    super(GeventWorker, self).init_process()
  File "/home/cl811/tools/miniconda3/envs/myenv/lib/python3.6/site-packages/gunicorn/workers/base.py", line 129, in init_process
    self.load_wsgi()
  File "/home/cl811/tools/miniconda3/envs/myenv/lib/python3.6/site-packages/gunicorn/workers/base.py", line 138, in load_wsgi
    self.wsgi = self.app.wsgi()
  File "/home/cl811/tools/miniconda3/envs/myenv/lib/python3.6/site-packages/gunicorn/app/base.py", line 67, in wsgi
    self.callable = self.load()
  File "/home/cl811/tools/miniconda3/envs/myenv/lib/python3.6/site-packages/gunicorn/app/wsgiapp.py", line 52, in load
    return self.load_wsgiapp()
  File "/home/cl811/tools/miniconda3/envs/myenv/lib/python3.6/site-packages/gunicorn/app/wsgiapp.py", line 41, in load_wsgiapp
    return util.import_app(self.app_uri)
  File "/home/cl811/tools/miniconda3/envs/myenv/lib/python3.6/site-packages/gunicorn/util.py", line 350, in import_app
    __import__(module)
  File "/home/cl811/work/19spring-courses/wsm/proj/ZDBK/run.py", line 3, in <module>
    app.run()
  File "/home/cl811/tools/miniconda3/envs/myenv/lib/python3.6/site-packages/flask/app.py", line 944, in run
    run_simple(host, port, self, **options)
  File "/home/cl811/tools/miniconda3/envs/myenv/lib/python3.6/site-packages/werkzeug/serving.py", line 987, in run_simple
    s.bind(server_address)
OSError: [Errno 98] Address already in use
[2019-06-13 15:46:05 +0800] [445] [INFO] Worker exiting (pid: 445)
[2019-06-13 15:46:05 +0800] [447] [ERROR] Exception in worker process
Traceback (most recent call last):
  File "/home/cl811/tools/miniconda3/envs/myenv/lib/python3.6/site-packages/gunicorn/arbiter.py", line 583, in spawn_worker
    worker.init_process()
  File "/home/cl811/tools/miniconda3/envs/myenv/lib/python3.6/site-packages/gunicorn/workers/ggevent.py", line 203, in init_process
    super(GeventWorker, self).init_process()
  File "/home/cl811/tools/miniconda3/envs/myenv/lib/python3.6/site-packages/gunicorn/workers/base.py", line 129, in init_process
    self.load_wsgi()
  File "/home/cl811/tools/miniconda3/envs/myenv/lib/python3.6/site-packages/gunicorn/workers/base.py", line 138, in load_wsgi
    self.wsgi = self.app.wsgi()
  File "/home/cl811/tools/miniconda3/envs/myenv/lib/python3.6/site-packages/gunicorn/app/base.py", line 67, in wsgi
    self.callable = self.load()
  File "/home/cl811/tools/miniconda3/envs/myenv/lib/python3.6/site-packages/gunicorn/app/wsgiapp.py", line 52, in load
    return self.load_wsgiapp()
  File "/home/cl811/tools/miniconda3/envs/myenv/lib/python3.6/site-packages/gunicorn/app/wsgiapp.py", line 41, in load_wsgiapp
    return util.import_app(self.app_uri)
  File "/home/cl811/tools/miniconda3/envs/myenv/lib/python3.6/site-packages/gunicorn/util.py", line 350, in import_app
    __import__(module)
  File "/home/cl811/work/19spring-courses/wsm/proj/ZDBK/run.py", line 3, in <module>
    app.run()
  File "/home/cl811/tools/miniconda3/envs/myenv/lib/python3.6/site-packages/flask/app.py", line 944, in run
    run_simple(host, port, self, **options)
  File "/home/cl811/tools/miniconda3/envs/myenv/lib/python3.6/site-packages/werkzeug/serving.py", line 987, in run_simple
    s.bind(server_address)
OSError: [Errno 98] Address already in use
[2019-06-13 15:46:05 +0800] [447] [INFO] Worker exiting (pid: 447)
[2019-06-13 15:46:05 +0800] [449] [ERROR] Exception in worker process
Traceback (most recent call last):
  File "/home/cl811/tools/miniconda3/envs/myenv/lib/python3.6/site-packages/gunicorn/arbiter.py", line 583, in spawn_worker
    worker.init_process()
  File "/home/cl811/tools/miniconda3/envs/myenv/lib/python3.6/site-packages/gunicorn/workers/ggevent.py", line 203, in init_process
    super(GeventWorker, self).init_process()
  File "/home/cl811/tools/miniconda3/envs/myenv/lib/python3.6/site-packages/gunicorn/workers/base.py", line 129, in init_process
    self.load_wsgi()
  File "/home/cl811/tools/miniconda3/envs/myenv/lib/python3.6/site-packages/gunicorn/workers/base.py", line 138, in load_wsgi
    self.wsgi = self.app.wsgi()
  File "/home/cl811/tools/miniconda3/envs/myenv/lib/python3.6/site-packages/gunicorn/app/base.py", line 67, in wsgi
    self.callable = self.load()
  File "/home/cl811/tools/miniconda3/envs/myenv/lib/python3.6/site-packages/gunicorn/app/wsgiapp.py", line 52, in load
    return self.load_wsgiapp()
  File "/home/cl811/tools/miniconda3/envs/myenv/lib/python3.6/site-packages/gunicorn/app/wsgiapp.py", line 41, in load_wsgiapp
    return util.import_app(self.app_uri)
  File "/home/cl811/tools/miniconda3/envs/myenv/lib/python3.6/site-packages/gunicorn/util.py", line 350, in import_app
    __import__(module)
  File "/home/cl811/work/19spring-courses/wsm/proj/ZDBK/run.py", line 3, in <module>
    app.run()
  File "/home/cl811/tools/miniconda3/envs/myenv/lib/python3.6/site-packages/flask/app.py", line 944, in run
    run_simple(host, port, self, **options)
  File "/home/cl811/tools/miniconda3/envs/myenv/lib/python3.6/site-packages/werkzeug/serving.py", line 987, in run_simple
    s.bind(server_address)
OSError: [Errno 98] Address already in use
[2019-06-13 15:46:05 +0800] [449] [INFO] Worker exiting (pid: 449)
[2019-06-13 15:46:05 +0800] [450] [ERROR] Exception in worker process
Traceback (most recent call last):
  File "/home/cl811/tools/miniconda3/envs/myenv/lib/python3.6/site-packages/gunicorn/arbiter.py", line 583, in spawn_worker
    worker.init_process()
  File "/home/cl811/tools/miniconda3/envs/myenv/lib/python3.6/site-packages/gunicorn/workers/ggevent.py", line 203, in init_process
    super(GeventWorker, self).init_process()
  File "/home/cl811/tools/miniconda3/envs/myenv/lib/python3.6/site-packages/gunicorn/workers/base.py", line 129, in init_process
    self.load_wsgi()
  File "/home/cl811/tools/miniconda3/envs/myenv/lib/python3.6/site-packages/gunicorn/workers/base.py", line 138, in load_wsgi
    self.wsgi = self.app.wsgi()
  File "/home/cl811/tools/miniconda3/envs/myenv/lib/python3.6/site-packages/gunicorn/app/base.py", line 67, in wsgi
    self.callable = self.load()
  File "/home/cl811/tools/miniconda3/envs/myenv/lib/python3.6/site-packages/gunicorn/app/wsgiapp.py", line 52, in load
    return self.load_wsgiapp()
  File "/home/cl811/tools/miniconda3/envs/myenv/lib/python3.6/site-packages/gunicorn/app/wsgiapp.py", line 41, in load_wsgiapp
    return util.import_app(self.app_uri)
  File "/home/cl811/tools/miniconda3/envs/myenv/lib/python3.6/site-packages/gunicorn/util.py", line 350, in import_app
    __import__(module)
  File "/home/cl811/work/19spring-courses/wsm/proj/ZDBK/run.py", line 3, in <module>
    app.run()
  File "/home/cl811/tools/miniconda3/envs/myenv/lib/python3.6/site-packages/flask/app.py", line 944, in run
    run_simple(host, port, self, **options)
  File "/home/cl811/tools/miniconda3/envs/myenv/lib/python3.6/site-packages/werkzeug/serving.py", line 987, in run_simple
    s.bind(server_address)
OSError: [Errno 98] Address already in use
[2019-06-13 15:46:05 +0800] [450] [INFO] Worker exiting (pid: 450)
[2019-06-13 15:46:35 +0800] [329] [CRITICAL] WORKER TIMEOUT (pid:445)
[2019-06-13 15:46:35 +0800] [329] [CRITICAL] WORKER TIMEOUT (pid:447)
[2019-06-13 15:46:35 +0800] [329] [CRITICAL] WORKER TIMEOUT (pid:449)
[2019-06-13 15:46:35 +0800] [329] [CRITICAL] WORKER TIMEOUT (pid:450)
[2019-06-13 15:46:35 +0800] [569] [INFO] Booting worker with pid: 569
[2019-06-13 15:46:35 +0800] [570] [INFO] Booting worker with pid: 570
[2019-06-13 15:46:35 +0800] [573] [INFO] Booting worker with pid: 573
[2019-06-13 15:46:35 +0800] [575] [INFO] Booting worker with pid: 575
[2019-06-13 15:46:35 +0800] [569] [ERROR] Exception in worker process
Traceback (most recent call last):
  File "/home/cl811/tools/miniconda3/envs/myenv/lib/python3.6/site-packages/gunicorn/arbiter.py", line 583, in spawn_worker
    worker.init_process()
  File "/home/cl811/tools/miniconda3/envs/myenv/lib/python3.6/site-packages/gunicorn/workers/ggevent.py", line 203, in init_process
    super(GeventWorker, self).init_process()
  File "/home/cl811/tools/miniconda3/envs/myenv/lib/python3.6/site-packages/gunicorn/workers/base.py", line 129, in init_process
    self.load_wsgi()
  File "/home/cl811/tools/miniconda3/envs/myenv/lib/python3.6/site-packages/gunicorn/workers/base.py", line 138, in load_wsgi
    self.wsgi = self.app.wsgi()
  File "/home/cl811/tools/miniconda3/envs/myenv/lib/python3.6/site-packages/gunicorn/app/base.py", line 67, in wsgi
    self.callable = self.load()
  File "/home/cl811/tools/miniconda3/envs/myenv/lib/python3.6/site-packages/gunicorn/app/wsgiapp.py", line 52, in load
    return self.load_wsgiapp()
  File "/home/cl811/tools/miniconda3/envs/myenv/lib/python3.6/site-packages/gunicorn/app/wsgiapp.py", line 41, in load_wsgiapp
    return util.import_app(self.app_uri)
  File "/home/cl811/tools/miniconda3/envs/myenv/lib/python3.6/site-packages/gunicorn/util.py", line 350, in import_app
    __import__(module)
  File "/home/cl811/work/19spring-courses/wsm/proj/ZDBK/run.py", line 3, in <module>
    app.run()
  File "/home/cl811/tools/miniconda3/envs/myenv/lib/python3.6/site-packages/flask/app.py", line 944, in run
    run_simple(host, port, self, **options)
  File "/home/cl811/tools/miniconda3/envs/myenv/lib/python3.6/site-packages/werkzeug/serving.py", line 987, in run_simple
    s.bind(server_address)
OSError: [Errno 98] Address already in use
[2019-06-13 15:46:35 +0800] [569] [INFO] Worker exiting (pid: 569)
[2019-06-13 15:46:35 +0800] [570] [ERROR] Exception in worker process
Traceback (most recent call last):
  File "/home/cl811/tools/miniconda3/envs/myenv/lib/python3.6/site-packages/gunicorn/arbiter.py", line 583, in spawn_worker
    worker.init_process()
  File "/home/cl811/tools/miniconda3/envs/myenv/lib/python3.6/site-packages/gunicorn/workers/ggevent.py", line 203, in init_process
    super(GeventWorker, self).init_process()
  File "/home/cl811/tools/miniconda3/envs/myenv/lib/python3.6/site-packages/gunicorn/workers/base.py", line 129, in init_process
    self.load_wsgi()
  File "/home/cl811/tools/miniconda3/envs/myenv/lib/python3.6/site-packages/gunicorn/workers/base.py", line 138, in load_wsgi
    self.wsgi = self.app.wsgi()
  File "/home/cl811/tools/miniconda3/envs/myenv/lib/python3.6/site-packages/gunicorn/app/base.py", line 67, in wsgi
    self.callable = self.load()
  File "/home/cl811/tools/miniconda3/envs/myenv/lib/python3.6/site-packages/gunicorn/app/wsgiapp.py", line 52, in load
    return self.load_wsgiapp()
  File "/home/cl811/tools/miniconda3/envs/myenv/lib/python3.6/site-packages/gunicorn/app/wsgiapp.py", line 41, in load_wsgiapp
    return util.import_app(self.app_uri)
  File "/home/cl811/tools/miniconda3/envs/myenv/lib/python3.6/site-packages/gunicorn/util.py", line 350, in import_app
    __import__(module)
  File "/home/cl811/work/19spring-courses/wsm/proj/ZDBK/run.py", line 3, in <module>
    app.run()
  File "/home/cl811/tools/miniconda3/envs/myenv/lib/python3.6/site-packages/flask/app.py", line 944, in run
    run_simple(host, port, self, **options)
  File "/home/cl811/tools/miniconda3/envs/myenv/lib/python3.6/site-packages/werkzeug/serving.py", line 987, in run_simple
    s.bind(server_address)
OSError: [Errno 98] Address already in use
[2019-06-13 15:46:35 +0800] [570] [INFO] Worker exiting (pid: 570)
[2019-06-13 15:46:35 +0800] [573] [ERROR] Exception in worker process
Traceback (most recent call last):
  File "/home/cl811/tools/miniconda3/envs/myenv/lib/python3.6/site-packages/gunicorn/arbiter.py", line 583, in spawn_worker
    worker.init_process()
  File "/home/cl811/tools/miniconda3/envs/myenv/lib/python3.6/site-packages/gunicorn/workers/ggevent.py", line 203, in init_process
    super(GeventWorker, self).init_process()
  File "/home/cl811/tools/miniconda3/envs/myenv/lib/python3.6/site-packages/gunicorn/workers/base.py", line 129, in init_process
    self.load_wsgi()
  File "/home/cl811/tools/miniconda3/envs/myenv/lib/python3.6/site-packages/gunicorn/workers/base.py", line 138, in load_wsgi
    self.wsgi = self.app.wsgi()
  File "/home/cl811/tools/miniconda3/envs/myenv/lib/python3.6/site-packages/gunicorn/app/base.py", line 67, in wsgi
    self.callable = self.load()
  File "/home/cl811/tools/miniconda3/envs/myenv/lib/python3.6/site-packages/gunicorn/app/wsgiapp.py", line 52, in load
    return self.load_wsgiapp()
  File "/home/cl811/tools/miniconda3/envs/myenv/lib/python3.6/site-packages/gunicorn/app/wsgiapp.py", line 41, in load_wsgiapp
    return util.import_app(self.app_uri)
  File "/home/cl811/tools/miniconda3/envs/myenv/lib/python3.6/site-packages/gunicorn/util.py", line 350, in import_app
    __import__(module)
  File "/home/cl811/work/19spring-courses/wsm/proj/ZDBK/run.py", line 3, in <module>
    app.run()
  File "/home/cl811/tools/miniconda3/envs/myenv/lib/python3.6/site-packages/flask/app.py", line 944, in run
    run_simple(host, port, self, **options)
  File "/home/cl811/tools/miniconda3/envs/myenv/lib/python3.6/site-packages/werkzeug/serving.py", line 987, in run_simple
    s.bind(server_address)
OSError: [Errno 98] Address already in use
[2019-06-13 15:46:35 +0800] [573] [INFO] Worker exiting (pid: 573)
[2019-06-13 15:46:35 +0800] [575] [ERROR] Exception in worker process
Traceback (most recent call last):
  File "/home/cl811/tools/miniconda3/envs/myenv/lib/python3.6/site-packages/gunicorn/arbiter.py", line 583, in spawn_worker
    worker.init_process()
  File "/home/cl811/tools/miniconda3/envs/myenv/lib/python3.6/site-packages/gunicorn/workers/ggevent.py", line 203, in init_process
    super(GeventWorker, self).init_process()
  File "/home/cl811/tools/miniconda3/envs/myenv/lib/python3.6/site-packages/gunicorn/workers/base.py", line 129, in init_process
    self.load_wsgi()
  File "/home/cl811/tools/miniconda3/envs/myenv/lib/python3.6/site-packages/gunicorn/workers/base.py", line 138, in load_wsgi
    self.wsgi = self.app.wsgi()
  File "/home/cl811/tools/miniconda3/envs/myenv/lib/python3.6/site-packages/gunicorn/app/base.py", line 67, in wsgi
    self.callable = self.load()
  File "/home/cl811/tools/miniconda3/envs/myenv/lib/python3.6/site-packages/gunicorn/app/wsgiapp.py", line 52, in load
    return self.load_wsgiapp()
  File "/home/cl811/tools/miniconda3/envs/myenv/lib/python3.6/site-packages/gunicorn/app/wsgiapp.py", line 41, in load_wsgiapp
    return util.import_app(self.app_uri)
  File "/home/cl811/tools/miniconda3/envs/myenv/lib/python3.6/site-packages/gunicorn/util.py", line 350, in import_app
    __import__(module)
  File "/home/cl811/work/19spring-courses/wsm/proj/ZDBK/run.py", line 3, in <module>
    app.run()
  File "/home/cl811/tools/miniconda3/envs/myenv/lib/python3.6/site-packages/flask/app.py", line 944, in run
    run_simple(host, port, self, **options)
  File "/home/cl811/tools/miniconda3/envs/myenv/lib/python3.6/site-packages/werkzeug/serving.py", line 987, in run_simple
    s.bind(server_address)
OSError: [Errno 98] Address already in use
[2019-06-13 15:46:35 +0800] [575] [INFO] Worker exiting (pid: 575)
[2019-06-13 15:46:55 +0800] [625] [DEBUG] Current configuration:
  config: config.py
  bind: ['127.0.0.1:5000']
  backlog: 2048
  workers: 4
  worker_class: gevent
  threads: 1
  worker_connections: 1000
  max_requests: 0
  max_requests_jitter: 0
  timeout: 30
  graceful_timeout: 30
  keepalive: 2
  limit_request_line: 4094
  limit_request_fields: 100
  limit_request_field_size: 8190
  reload: False
  reload_engine: auto
  reload_extra_files: []
  spew: False
  check_config: False
  preload_app: False
  sendfile: None
  reuse_port: False
  chdir: /home/cl811/work/19spring-courses/wsm/proj/ZDBK
  daemon: True
  raw_env: []
  pidfile: log/gunicorn.pid
  worker_tmp_dir: None
  user: 1000
  group: 1000
  umask: 0
  initgroups: False
  tmp_upload_dir: None
  secure_scheme_headers: {'X-FORWARDED-PROTOCOL': 'ssl', 'X-FORWARDED-PROTO': 'https', 'X-FORWARDED-SSL': 'on'}
  forwarded_allow_ips: ['127.0.0.1']
  accesslog: log/access.log
  disable_redirect_access_to_syslog: False
  access_log_format: %(h)s %(l)s %(u)s %(t)s "%(r)s" %(s)s %(b)s "%(f)s" "%(a)s"
  errorlog: log/debug.log
  loglevel: debug
  capture_output: False
  logger_class: gunicorn.glogging.Logger
  logconfig: None
  logconfig_dict: {}
  syslog_addr: udp://localhost:514
  syslog: False
  syslog_prefix: None
  syslog_facility: user
  enable_stdio_inheritance: False
  statsd_host: None
  statsd_prefix: 
  proc_name: None
  default_proc_name: run:app
  pythonpath: None
  paste: None
  on_starting: <function OnStarting.on_starting at 0x7f7192973378>
  on_reload: <function OnReload.on_reload at 0x7f7192973488>
  when_ready: <function WhenReady.when_ready at 0x7f7192973598>
  pre_fork: <function Prefork.pre_fork at 0x7f71929736a8>
  post_fork: <function Postfork.post_fork at 0x7f71929737b8>
  post_worker_init: <function PostWorkerInit.post_worker_init at 0x7f71929738c8>
  worker_int: <function WorkerInt.worker_int at 0x7f71929739d8>
  worker_abort: <function WorkerAbort.worker_abort at 0x7f7192973ae8>
  pre_exec: <function PreExec.pre_exec at 0x7f7192973bf8>
  pre_request: <function PreRequest.pre_request at 0x7f7192973d08>
  post_request: <function PostRequest.post_request at 0x7f7192973d90>
  child_exit: <function ChildExit.child_exit at 0x7f7192973ea0>
  worker_exit: <function WorkerExit.worker_exit at 0x7f7192991048>
  nworkers_changed: <function NumWorkersChanged.nworkers_changed at 0x7f7192991158>
  on_exit: <function OnExit.on_exit at 0x7f7192991268>
  proxy_protocol: False
  proxy_allow_ips: ['127.0.0.1']
  keyfile: None
  certfile: None
  ssl_version: 2
  cert_reqs: 0
  ca_certs: None
  suppress_ragged_eofs: True
  do_handshake_on_connect: False
  ciphers: TLSv1
  raw_paste_global_conf: []
[2019-06-13 15:46:55 +0800] [625] [INFO] Starting gunicorn 19.9.0
[2019-06-13 15:47:05 +0800] [329] [CRITICAL] WORKER TIMEOUT (pid:569)
[2019-06-13 15:47:05 +0800] [329] [CRITICAL] WORKER TIMEOUT (pid:570)
[2019-06-13 15:47:05 +0800] [329] [CRITICAL] WORKER TIMEOUT (pid:573)
[2019-06-13 15:47:05 +0800] [329] [CRITICAL] WORKER TIMEOUT (pid:575)
[2019-06-13 15:47:05 +0800] [673] [INFO] Booting worker with pid: 673
[2019-06-13 15:47:05 +0800] [674] [INFO] Booting worker with pid: 674
[2019-06-13 15:47:05 +0800] [677] [INFO] Booting worker with pid: 677
[2019-06-13 15:47:05 +0800] [678] [INFO] Booting worker with pid: 678
[2019-06-13 15:47:05 +0800] [674] [ERROR] Exception in worker process
Traceback (most recent call last):
  File "/home/cl811/tools/miniconda3/envs/myenv/lib/python3.6/site-packages/gunicorn/arbiter.py", line 583, in spawn_worker
    worker.init_process()
  File "/home/cl811/tools/miniconda3/envs/myenv/lib/python3.6/site-packages/gunicorn/workers/ggevent.py", line 203, in init_process
    super(GeventWorker, self).init_process()
  File "/home/cl811/tools/miniconda3/envs/myenv/lib/python3.6/site-packages/gunicorn/workers/base.py", line 129, in init_process
    self.load_wsgi()
  File "/home/cl811/tools/miniconda3/envs/myenv/lib/python3.6/site-packages/gunicorn/workers/base.py", line 138, in load_wsgi
    self.wsgi = self.app.wsgi()
  File "/home/cl811/tools/miniconda3/envs/myenv/lib/python3.6/site-packages/gunicorn/app/base.py", line 67, in wsgi
    self.callable = self.load()
  File "/home/cl811/tools/miniconda3/envs/myenv/lib/python3.6/site-packages/gunicorn/app/wsgiapp.py", line 52, in load
    return self.load_wsgiapp()
  File "/home/cl811/tools/miniconda3/envs/myenv/lib/python3.6/site-packages/gunicorn/app/wsgiapp.py", line 41, in load_wsgiapp
    return util.import_app(self.app_uri)
  File "/home/cl811/tools/miniconda3/envs/myenv/lib/python3.6/site-packages/gunicorn/util.py", line 350, in import_app
    __import__(module)
  File "/home/cl811/work/19spring-courses/wsm/proj/ZDBK/run.py", line 3, in <module>
    app.run()
  File "/home/cl811/tools/miniconda3/envs/myenv/lib/python3.6/site-packages/flask/app.py", line 944, in run
    run_simple(host, port, self, **options)
  File "/home/cl811/tools/miniconda3/envs/myenv/lib/python3.6/site-packages/werkzeug/serving.py", line 987, in run_simple
    s.bind(server_address)
OSError: [Errno 98] Address already in use
[2019-06-13 15:47:05 +0800] [674] [INFO] Worker exiting (pid: 674)
[2019-06-13 15:47:05 +0800] [673] [ERROR] Exception in worker process
Traceback (most recent call last):
  File "/home/cl811/tools/miniconda3/envs/myenv/lib/python3.6/site-packages/gunicorn/arbiter.py", line 583, in spawn_worker
    worker.init_process()
  File "/home/cl811/tools/miniconda3/envs/myenv/lib/python3.6/site-packages/gunicorn/workers/ggevent.py", line 203, in init_process
    super(GeventWorker, self).init_process()
  File "/home/cl811/tools/miniconda3/envs/myenv/lib/python3.6/site-packages/gunicorn/workers/base.py", line 129, in init_process
    self.load_wsgi()
  File "/home/cl811/tools/miniconda3/envs/myenv/lib/python3.6/site-packages/gunicorn/workers/base.py", line 138, in load_wsgi
    self.wsgi = self.app.wsgi()
  File "/home/cl811/tools/miniconda3/envs/myenv/lib/python3.6/site-packages/gunicorn/app/base.py", line 67, in wsgi
    self.callable = self.load()
  File "/home/cl811/tools/miniconda3/envs/myenv/lib/python3.6/site-packages/gunicorn/app/wsgiapp.py", line 52, in load
    return self.load_wsgiapp()
  File "/home/cl811/tools/miniconda3/envs/myenv/lib/python3.6/site-packages/gunicorn/app/wsgiapp.py", line 41, in load_wsgiapp
    return util.import_app(self.app_uri)
  File "/home/cl811/tools/miniconda3/envs/myenv/lib/python3.6/site-packages/gunicorn/util.py", line 350, in import_app
    __import__(module)
  File "/home/cl811/work/19spring-courses/wsm/proj/ZDBK/run.py", line 3, in <module>
    app.run()
  File "/home/cl811/tools/miniconda3/envs/myenv/lib/python3.6/site-packages/flask/app.py", line 944, in run
    run_simple(host, port, self, **options)
  File "/home/cl811/tools/miniconda3/envs/myenv/lib/python3.6/site-packages/werkzeug/serving.py", line 987, in run_simple
    s.bind(server_address)
OSError: [Errno 98] Address already in use
[2019-06-13 15:47:05 +0800] [673] [INFO] Worker exiting (pid: 673)
[2019-06-13 15:47:06 +0800] [677] [ERROR] Exception in worker process
Traceback (most recent call last):
  File "/home/cl811/tools/miniconda3/envs/myenv/lib/python3.6/site-packages/gunicorn/arbiter.py", line 583, in spawn_worker
    worker.init_process()
  File "/home/cl811/tools/miniconda3/envs/myenv/lib/python3.6/site-packages/gunicorn/workers/ggevent.py", line 203, in init_process
    super(GeventWorker, self).init_process()
  File "/home/cl811/tools/miniconda3/envs/myenv/lib/python3.6/site-packages/gunicorn/workers/base.py", line 129, in init_process
    self.load_wsgi()
  File "/home/cl811/tools/miniconda3/envs/myenv/lib/python3.6/site-packages/gunicorn/workers/base.py", line 138, in load_wsgi
    self.wsgi = self.app.wsgi()
  File "/home/cl811/tools/miniconda3/envs/myenv/lib/python3.6/site-packages/gunicorn/app/base.py", line 67, in wsgi
    self.callable = self.load()
  File "/home/cl811/tools/miniconda3/envs/myenv/lib/python3.6/site-packages/gunicorn/app/wsgiapp.py", line 52, in load
    return self.load_wsgiapp()
  File "/home/cl811/tools/miniconda3/envs/myenv/lib/python3.6/site-packages/gunicorn/app/wsgiapp.py", line 41, in load_wsgiapp
    return util.import_app(self.app_uri)
  File "/home/cl811/tools/miniconda3/envs/myenv/lib/python3.6/site-packages/gunicorn/util.py", line 350, in import_app
    __import__(module)
  File "/home/cl811/work/19spring-courses/wsm/proj/ZDBK/run.py", line 3, in <module>
    app.run()
  File "/home/cl811/tools/miniconda3/envs/myenv/lib/python3.6/site-packages/flask/app.py", line 944, in run
    run_simple(host, port, self, **options)
  File "/home/cl811/tools/miniconda3/envs/myenv/lib/python3.6/site-packages/werkzeug/serving.py", line 987, in run_simple
    s.bind(server_address)
OSError: [Errno 98] Address already in use
[2019-06-13 15:47:06 +0800] [677] [INFO] Worker exiting (pid: 677)
[2019-06-13 15:47:06 +0800] [678] [ERROR] Exception in worker process
Traceback (most recent call last):
  File "/home/cl811/tools/miniconda3/envs/myenv/lib/python3.6/site-packages/gunicorn/arbiter.py", line 583, in spawn_worker
    worker.init_process()
  File "/home/cl811/tools/miniconda3/envs/myenv/lib/python3.6/site-packages/gunicorn/workers/ggevent.py", line 203, in init_process
    super(GeventWorker, self).init_process()
  File "/home/cl811/tools/miniconda3/envs/myenv/lib/python3.6/site-packages/gunicorn/workers/base.py", line 129, in init_process
    self.load_wsgi()
  File "/home/cl811/tools/miniconda3/envs/myenv/lib/python3.6/site-packages/gunicorn/workers/base.py", line 138, in load_wsgi
    self.wsgi = self.app.wsgi()
  File "/home/cl811/tools/miniconda3/envs/myenv/lib/python3.6/site-packages/gunicorn/app/base.py", line 67, in wsgi
    self.callable = self.load()
  File "/home/cl811/tools/miniconda3/envs/myenv/lib/python3.6/site-packages/gunicorn/app/wsgiapp.py", line 52, in load
    return self.load_wsgiapp()
  File "/home/cl811/tools/miniconda3/envs/myenv/lib/python3.6/site-packages/gunicorn/app/wsgiapp.py", line 41, in load_wsgiapp
    return util.import_app(self.app_uri)
  File "/home/cl811/tools/miniconda3/envs/myenv/lib/python3.6/site-packages/gunicorn/util.py", line 350, in import_app
    __import__(module)
  File "/home/cl811/work/19spring-courses/wsm/proj/ZDBK/run.py", line 3, in <module>
    app.run()
  File "/home/cl811/tools/miniconda3/envs/myenv/lib/python3.6/site-packages/flask/app.py", line 944, in run
    run_simple(host, port, self, **options)
  File "/home/cl811/tools/miniconda3/envs/myenv/lib/python3.6/site-packages/werkzeug/serving.py", line 987, in run_simple
    s.bind(server_address)
OSError: [Errno 98] Address already in use
[2019-06-13 15:47:06 +0800] [678] [INFO] Worker exiting (pid: 678)
[2019-06-13 15:47:06 +0800] [685] [DEBUG] Current configuration:
  config: config.py
  bind: ['127.0.0.1:5000']
  backlog: 2048
  workers: 4
  worker_class: gevent
  threads: 1
  worker_connections: 1000
  max_requests: 0
  max_requests_jitter: 0
  timeout: 30
  graceful_timeout: 30
  keepalive: 2
  limit_request_line: 4094
  limit_request_fields: 100
  limit_request_field_size: 8190
  reload: False
  reload_engine: auto
  reload_extra_files: []
  spew: False
  check_config: False
  preload_app: False
  sendfile: None
  reuse_port: False
  chdir: /home/cl811/work/19spring-courses/wsm/proj/ZDBK
  daemon: False
  raw_env: []
  pidfile: log/gunicorn.pid
  worker_tmp_dir: None
  user: 1000
  group: 1000
  umask: 0
  initgroups: False
  tmp_upload_dir: None
  secure_scheme_headers: {'X-FORWARDED-PROTOCOL': 'ssl', 'X-FORWARDED-PROTO': 'https', 'X-FORWARDED-SSL': 'on'}
  forwarded_allow_ips: ['127.0.0.1']
  accesslog: log/access.log
  disable_redirect_access_to_syslog: False
  access_log_format: %(h)s %(l)s %(u)s %(t)s "%(r)s" %(s)s %(b)s "%(f)s" "%(a)s"
  errorlog: log/debug.log
  loglevel: debug
  capture_output: False
  logger_class: gunicorn.glogging.Logger
  logconfig: None
  logconfig_dict: {}
  syslog_addr: udp://localhost:514
  syslog: False
  syslog_prefix: None
  syslog_facility: user
  enable_stdio_inheritance: False
  statsd_host: None
  statsd_prefix: 
  proc_name: None
  default_proc_name: run:app
  pythonpath: None
  paste: None
  on_starting: <function OnStarting.on_starting at 0x7fd800465378>
  on_reload: <function OnReload.on_reload at 0x7fd800465488>
  when_ready: <function WhenReady.when_ready at 0x7fd800465598>
  pre_fork: <function Prefork.pre_fork at 0x7fd8004656a8>
  post_fork: <function Postfork.post_fork at 0x7fd8004657b8>
  post_worker_init: <function PostWorkerInit.post_worker_init at 0x7fd8004658c8>
  worker_int: <function WorkerInt.worker_int at 0x7fd8004659d8>
  worker_abort: <function WorkerAbort.worker_abort at 0x7fd800465ae8>
  pre_exec: <function PreExec.pre_exec at 0x7fd800465bf8>
  pre_request: <function PreRequest.pre_request at 0x7fd800465d08>
  post_request: <function PostRequest.post_request at 0x7fd800465d90>
  child_exit: <function ChildExit.child_exit at 0x7fd800465ea0>
  worker_exit: <function WorkerExit.worker_exit at 0x7fd800483048>
  nworkers_changed: <function NumWorkersChanged.nworkers_changed at 0x7fd800483158>
  on_exit: <function OnExit.on_exit at 0x7fd800483268>
  proxy_protocol: False
  proxy_allow_ips: ['127.0.0.1']
  keyfile: None
  certfile: None
  ssl_version: 2
  cert_reqs: 0
  ca_certs: None
  suppress_ragged_eofs: True
  do_handshake_on_connect: False
  ciphers: TLSv1
  raw_paste_global_conf: []
[2019-06-13 15:47:06 +0800] [685] [INFO] Starting gunicorn 19.9.0
[2019-06-13 15:47:35 +0800] [329] [CRITICAL] WORKER TIMEOUT (pid:673)
[2019-06-13 15:47:35 +0800] [329] [CRITICAL] WORKER TIMEOUT (pid:674)
[2019-06-13 15:47:35 +0800] [329] [CRITICAL] WORKER TIMEOUT (pid:677)
[2019-06-13 15:47:35 +0800] [329] [CRITICAL] WORKER TIMEOUT (pid:678)
[2019-06-13 15:47:35 +0800] [848] [INFO] Booting worker with pid: 848
[2019-06-13 15:47:35 +0800] [849] [INFO] Booting worker with pid: 849
[2019-06-13 15:47:35 +0800] [853] [INFO] Booting worker with pid: 853
[2019-06-13 15:47:35 +0800] [857] [INFO] Booting worker with pid: 857
[2019-06-13 15:47:36 +0800] [848] [ERROR] Exception in worker process
Traceback (most recent call last):
  File "/home/cl811/tools/miniconda3/envs/myenv/lib/python3.6/site-packages/gunicorn/arbiter.py", line 583, in spawn_worker
    worker.init_process()
  File "/home/cl811/tools/miniconda3/envs/myenv/lib/python3.6/site-packages/gunicorn/workers/ggevent.py", line 203, in init_process
    super(GeventWorker, self).init_process()
  File "/home/cl811/tools/miniconda3/envs/myenv/lib/python3.6/site-packages/gunicorn/workers/base.py", line 129, in init_process
    self.load_wsgi()
  File "/home/cl811/tools/miniconda3/envs/myenv/lib/python3.6/site-packages/gunicorn/workers/base.py", line 138, in load_wsgi
    self.wsgi = self.app.wsgi()
  File "/home/cl811/tools/miniconda3/envs/myenv/lib/python3.6/site-packages/gunicorn/app/base.py", line 67, in wsgi
    self.callable = self.load()
  File "/home/cl811/tools/miniconda3/envs/myenv/lib/python3.6/site-packages/gunicorn/app/wsgiapp.py", line 52, in load
    return self.load_wsgiapp()
  File "/home/cl811/tools/miniconda3/envs/myenv/lib/python3.6/site-packages/gunicorn/app/wsgiapp.py", line 41, in load_wsgiapp
    return util.import_app(self.app_uri)
  File "/home/cl811/tools/miniconda3/envs/myenv/lib/python3.6/site-packages/gunicorn/util.py", line 350, in import_app
    __import__(module)
  File "/home/cl811/work/19spring-courses/wsm/proj/ZDBK/run.py", line 3, in <module>
    app.run()
  File "/home/cl811/tools/miniconda3/envs/myenv/lib/python3.6/site-packages/flask/app.py", line 944, in run
    run_simple(host, port, self, **options)
  File "/home/cl811/tools/miniconda3/envs/myenv/lib/python3.6/site-packages/werkzeug/serving.py", line 987, in run_simple
    s.bind(server_address)
OSError: [Errno 98] Address already in use
[2019-06-13 15:47:36 +0800] [848] [INFO] Worker exiting (pid: 848)
[2019-06-13 15:47:36 +0800] [849] [ERROR] Exception in worker process
Traceback (most recent call last):
  File "/home/cl811/tools/miniconda3/envs/myenv/lib/python3.6/site-packages/gunicorn/arbiter.py", line 583, in spawn_worker
    worker.init_process()
  File "/home/cl811/tools/miniconda3/envs/myenv/lib/python3.6/site-packages/gunicorn/workers/ggevent.py", line 203, in init_process
    super(GeventWorker, self).init_process()
  File "/home/cl811/tools/miniconda3/envs/myenv/lib/python3.6/site-packages/gunicorn/workers/base.py", line 129, in init_process
    self.load_wsgi()
  File "/home/cl811/tools/miniconda3/envs/myenv/lib/python3.6/site-packages/gunicorn/workers/base.py", line 138, in load_wsgi
    self.wsgi = self.app.wsgi()
  File "/home/cl811/tools/miniconda3/envs/myenv/lib/python3.6/site-packages/gunicorn/app/base.py", line 67, in wsgi
    self.callable = self.load()
  File "/home/cl811/tools/miniconda3/envs/myenv/lib/python3.6/site-packages/gunicorn/app/wsgiapp.py", line 52, in load
    return self.load_wsgiapp()
  File "/home/cl811/tools/miniconda3/envs/myenv/lib/python3.6/site-packages/gunicorn/app/wsgiapp.py", line 41, in load_wsgiapp
    return util.import_app(self.app_uri)
  File "/home/cl811/tools/miniconda3/envs/myenv/lib/python3.6/site-packages/gunicorn/util.py", line 350, in import_app
    __import__(module)
  File "/home/cl811/work/19spring-courses/wsm/proj/ZDBK/run.py", line 3, in <module>
    app.run()
  File "/home/cl811/tools/miniconda3/envs/myenv/lib/python3.6/site-packages/flask/app.py", line 944, in run
    run_simple(host, port, self, **options)
  File "/home/cl811/tools/miniconda3/envs/myenv/lib/python3.6/site-packages/werkzeug/serving.py", line 987, in run_simple
    s.bind(server_address)
OSError: [Errno 98] Address already in use
[2019-06-13 15:47:36 +0800] [849] [INFO] Worker exiting (pid: 849)
[2019-06-13 15:47:36 +0800] [853] [ERROR] Exception in worker process
Traceback (most recent call last):
  File "/home/cl811/tools/miniconda3/envs/myenv/lib/python3.6/site-packages/gunicorn/arbiter.py", line 583, in spawn_worker
    worker.init_process()
  File "/home/cl811/tools/miniconda3/envs/myenv/lib/python3.6/site-packages/gunicorn/workers/ggevent.py", line 203, in init_process
    super(GeventWorker, self).init_process()
  File "/home/cl811/tools/miniconda3/envs/myenv/lib/python3.6/site-packages/gunicorn/workers/base.py", line 129, in init_process
    self.load_wsgi()
  File "/home/cl811/tools/miniconda3/envs/myenv/lib/python3.6/site-packages/gunicorn/workers/base.py", line 138, in load_wsgi
    self.wsgi = self.app.wsgi()
  File "/home/cl811/tools/miniconda3/envs/myenv/lib/python3.6/site-packages/gunicorn/app/base.py", line 67, in wsgi
    self.callable = self.load()
  File "/home/cl811/tools/miniconda3/envs/myenv/lib/python3.6/site-packages/gunicorn/app/wsgiapp.py", line 52, in load
    return self.load_wsgiapp()
  File "/home/cl811/tools/miniconda3/envs/myenv/lib/python3.6/site-packages/gunicorn/app/wsgiapp.py", line 41, in load_wsgiapp
    return util.import_app(self.app_uri)
  File "/home/cl811/tools/miniconda3/envs/myenv/lib/python3.6/site-packages/gunicorn/util.py", line 350, in import_app
    __import__(module)
  File "/home/cl811/work/19spring-courses/wsm/proj/ZDBK/run.py", line 3, in <module>
    app.run()
  File "/home/cl811/tools/miniconda3/envs/myenv/lib/python3.6/site-packages/flask/app.py", line 944, in run
    run_simple(host, port, self, **options)
  File "/home/cl811/tools/miniconda3/envs/myenv/lib/python3.6/site-packages/werkzeug/serving.py", line 987, in run_simple
    s.bind(server_address)
OSError: [Errno 98] Address already in use
[2019-06-13 15:47:36 +0800] [853] [INFO] Worker exiting (pid: 853)
[2019-06-13 15:47:36 +0800] [857] [ERROR] Exception in worker process
Traceback (most recent call last):
  File "/home/cl811/tools/miniconda3/envs/myenv/lib/python3.6/site-packages/gunicorn/arbiter.py", line 583, in spawn_worker
    worker.init_process()
  File "/home/cl811/tools/miniconda3/envs/myenv/lib/python3.6/site-packages/gunicorn/workers/ggevent.py", line 203, in init_process
    super(GeventWorker, self).init_process()
  File "/home/cl811/tools/miniconda3/envs/myenv/lib/python3.6/site-packages/gunicorn/workers/base.py", line 129, in init_process
    self.load_wsgi()
  File "/home/cl811/tools/miniconda3/envs/myenv/lib/python3.6/site-packages/gunicorn/workers/base.py", line 138, in load_wsgi
    self.wsgi = self.app.wsgi()
  File "/home/cl811/tools/miniconda3/envs/myenv/lib/python3.6/site-packages/gunicorn/app/base.py", line 67, in wsgi
    self.callable = self.load()
  File "/home/cl811/tools/miniconda3/envs/myenv/lib/python3.6/site-packages/gunicorn/app/wsgiapp.py", line 52, in load
    return self.load_wsgiapp()
  File "/home/cl811/tools/miniconda3/envs/myenv/lib/python3.6/site-packages/gunicorn/app/wsgiapp.py", line 41, in load_wsgiapp
    return util.import_app(self.app_uri)
  File "/home/cl811/tools/miniconda3/envs/myenv/lib/python3.6/site-packages/gunicorn/util.py", line 350, in import_app
    __import__(module)
  File "/home/cl811/work/19spring-courses/wsm/proj/ZDBK/run.py", line 3, in <module>
    app.run()
  File "/home/cl811/tools/miniconda3/envs/myenv/lib/python3.6/site-packages/flask/app.py", line 944, in run
    run_simple(host, port, self, **options)
  File "/home/cl811/tools/miniconda3/envs/myenv/lib/python3.6/site-packages/werkzeug/serving.py", line 987, in run_simple
    s.bind(server_address)
OSError: [Errno 98] Address already in use
[2019-06-13 15:47:36 +0800] [857] [INFO] Worker exiting (pid: 857)
[2019-06-13 15:48:05 +0800] [329] [CRITICAL] WORKER TIMEOUT (pid:848)
[2019-06-13 15:48:05 +0800] [329] [CRITICAL] WORKER TIMEOUT (pid:849)
[2019-06-13 15:48:05 +0800] [329] [CRITICAL] WORKER TIMEOUT (pid:853)
[2019-06-13 15:48:05 +0800] [329] [CRITICAL] WORKER TIMEOUT (pid:857)
[2019-06-13 15:48:05 +0800] [877] [INFO] Booting worker with pid: 877
[2019-06-13 15:48:05 +0800] [879] [INFO] Booting worker with pid: 879
[2019-06-13 15:48:05 +0800] [880] [INFO] Booting worker with pid: 880
[2019-06-13 15:48:06 +0800] [884] [INFO] Booting worker with pid: 884
[2019-06-13 15:48:06 +0800] [879] [ERROR] Exception in worker process
Traceback (most recent call last):
  File "/home/cl811/tools/miniconda3/envs/myenv/lib/python3.6/site-packages/gunicorn/arbiter.py", line 583, in spawn_worker
    worker.init_process()
  File "/home/cl811/tools/miniconda3/envs/myenv/lib/python3.6/site-packages/gunicorn/workers/ggevent.py", line 203, in init_process
    super(GeventWorker, self).init_process()
  File "/home/cl811/tools/miniconda3/envs/myenv/lib/python3.6/site-packages/gunicorn/workers/base.py", line 129, in init_process
    self.load_wsgi()
  File "/home/cl811/tools/miniconda3/envs/myenv/lib/python3.6/site-packages/gunicorn/workers/base.py", line 138, in load_wsgi
    self.wsgi = self.app.wsgi()
  File "/home/cl811/tools/miniconda3/envs/myenv/lib/python3.6/site-packages/gunicorn/app/base.py", line 67, in wsgi
    self.callable = self.load()
  File "/home/cl811/tools/miniconda3/envs/myenv/lib/python3.6/site-packages/gunicorn/app/wsgiapp.py", line 52, in load
    return self.load_wsgiapp()
  File "/home/cl811/tools/miniconda3/envs/myenv/lib/python3.6/site-packages/gunicorn/app/wsgiapp.py", line 41, in load_wsgiapp
    return util.import_app(self.app_uri)
  File "/home/cl811/tools/miniconda3/envs/myenv/lib/python3.6/site-packages/gunicorn/util.py", line 350, in import_app
    __import__(module)
  File "/home/cl811/work/19spring-courses/wsm/proj/ZDBK/run.py", line 3, in <module>
    app.run()
  File "/home/cl811/tools/miniconda3/envs/myenv/lib/python3.6/site-packages/flask/app.py", line 944, in run
    run_simple(host, port, self, **options)
  File "/home/cl811/tools/miniconda3/envs/myenv/lib/python3.6/site-packages/werkzeug/serving.py", line 987, in run_simple
    s.bind(server_address)
OSError: [Errno 98] Address already in use
[2019-06-13 15:48:06 +0800] [879] [INFO] Worker exiting (pid: 879)
[2019-06-13 15:48:06 +0800] [880] [ERROR] Exception in worker process
Traceback (most recent call last):
  File "/home/cl811/tools/miniconda3/envs/myenv/lib/python3.6/site-packages/gunicorn/arbiter.py", line 583, in spawn_worker
    worker.init_process()
  File "/home/cl811/tools/miniconda3/envs/myenv/lib/python3.6/site-packages/gunicorn/workers/ggevent.py", line 203, in init_process
    super(GeventWorker, self).init_process()
  File "/home/cl811/tools/miniconda3/envs/myenv/lib/python3.6/site-packages/gunicorn/workers/base.py", line 129, in init_process
    self.load_wsgi()
  File "/home/cl811/tools/miniconda3/envs/myenv/lib/python3.6/site-packages/gunicorn/workers/base.py", line 138, in load_wsgi
    self.wsgi = self.app.wsgi()
  File "/home/cl811/tools/miniconda3/envs/myenv/lib/python3.6/site-packages/gunicorn/app/base.py", line 67, in wsgi
    self.callable = self.load()
  File "/home/cl811/tools/miniconda3/envs/myenv/lib/python3.6/site-packages/gunicorn/app/wsgiapp.py", line 52, in load
    return self.load_wsgiapp()
  File "/home/cl811/tools/miniconda3/envs/myenv/lib/python3.6/site-packages/gunicorn/app/wsgiapp.py", line 41, in load_wsgiapp
    return util.import_app(self.app_uri)
  File "/home/cl811/tools/miniconda3/envs/myenv/lib/python3.6/site-packages/gunicorn/util.py", line 350, in import_app
    __import__(module)
  File "/home/cl811/work/19spring-courses/wsm/proj/ZDBK/run.py", line 3, in <module>
    app.run()
  File "/home/cl811/tools/miniconda3/envs/myenv/lib/python3.6/site-packages/flask/app.py", line 944, in run
    run_simple(host, port, self, **options)
  File "/home/cl811/tools/miniconda3/envs/myenv/lib/python3.6/site-packages/werkzeug/serving.py", line 987, in run_simple
    s.bind(server_address)
OSError: [Errno 98] Address already in use
[2019-06-13 15:48:06 +0800] [880] [INFO] Worker exiting (pid: 880)
[2019-06-13 15:48:06 +0800] [877] [ERROR] Exception in worker process
Traceback (most recent call last):
  File "/home/cl811/tools/miniconda3/envs/myenv/lib/python3.6/site-packages/gunicorn/arbiter.py", line 583, in spawn_worker
    worker.init_process()
  File "/home/cl811/tools/miniconda3/envs/myenv/lib/python3.6/site-packages/gunicorn/workers/ggevent.py", line 203, in init_process
    super(GeventWorker, self).init_process()
  File "/home/cl811/tools/miniconda3/envs/myenv/lib/python3.6/site-packages/gunicorn/workers/base.py", line 129, in init_process
    self.load_wsgi()
  File "/home/cl811/tools/miniconda3/envs/myenv/lib/python3.6/site-packages/gunicorn/workers/base.py", line 138, in load_wsgi
    self.wsgi = self.app.wsgi()
  File "/home/cl811/tools/miniconda3/envs/myenv/lib/python3.6/site-packages/gunicorn/app/base.py", line 67, in wsgi
    self.callable = self.load()
  File "/home/cl811/tools/miniconda3/envs/myenv/lib/python3.6/site-packages/gunicorn/app/wsgiapp.py", line 52, in load
    return self.load_wsgiapp()
  File "/home/cl811/tools/miniconda3/envs/myenv/lib/python3.6/site-packages/gunicorn/app/wsgiapp.py", line 41, in load_wsgiapp
    return util.import_app(self.app_uri)
  File "/home/cl811/tools/miniconda3/envs/myenv/lib/python3.6/site-packages/gunicorn/util.py", line 350, in import_app
    __import__(module)
  File "/home/cl811/work/19spring-courses/wsm/proj/ZDBK/run.py", line 3, in <module>
    app.run()
  File "/home/cl811/tools/miniconda3/envs/myenv/lib/python3.6/site-packages/flask/app.py", line 944, in run
    run_simple(host, port, self, **options)
  File "/home/cl811/tools/miniconda3/envs/myenv/lib/python3.6/site-packages/werkzeug/serving.py", line 987, in run_simple
    s.bind(server_address)
OSError: [Errno 98] Address already in use
[2019-06-13 15:48:06 +0800] [877] [INFO] Worker exiting (pid: 877)
[2019-06-13 15:48:06 +0800] [884] [ERROR] Exception in worker process
Traceback (most recent call last):
  File "/home/cl811/tools/miniconda3/envs/myenv/lib/python3.6/site-packages/gunicorn/arbiter.py", line 583, in spawn_worker
    worker.init_process()
  File "/home/cl811/tools/miniconda3/envs/myenv/lib/python3.6/site-packages/gunicorn/workers/ggevent.py", line 203, in init_process
    super(GeventWorker, self).init_process()
  File "/home/cl811/tools/miniconda3/envs/myenv/lib/python3.6/site-packages/gunicorn/workers/base.py", line 129, in init_process
    self.load_wsgi()
  File "/home/cl811/tools/miniconda3/envs/myenv/lib/python3.6/site-packages/gunicorn/workers/base.py", line 138, in load_wsgi
    self.wsgi = self.app.wsgi()
  File "/home/cl811/tools/miniconda3/envs/myenv/lib/python3.6/site-packages/gunicorn/app/base.py", line 67, in wsgi
    self.callable = self.load()
  File "/home/cl811/tools/miniconda3/envs/myenv/lib/python3.6/site-packages/gunicorn/app/wsgiapp.py", line 52, in load
    return self.load_wsgiapp()
  File "/home/cl811/tools/miniconda3/envs/myenv/lib/python3.6/site-packages/gunicorn/app/wsgiapp.py", line 41, in load_wsgiapp
    return util.import_app(self.app_uri)
  File "/home/cl811/tools/miniconda3/envs/myenv/lib/python3.6/site-packages/gunicorn/util.py", line 350, in import_app
    __import__(module)
  File "/home/cl811/work/19spring-courses/wsm/proj/ZDBK/run.py", line 3, in <module>
    app.run()
  File "/home/cl811/tools/miniconda3/envs/myenv/lib/python3.6/site-packages/flask/app.py", line 944, in run
    run_simple(host, port, self, **options)
  File "/home/cl811/tools/miniconda3/envs/myenv/lib/python3.6/site-packages/werkzeug/serving.py", line 987, in run_simple
    s.bind(server_address)
OSError: [Errno 98] Address already in use
[2019-06-13 15:48:06 +0800] [884] [INFO] Worker exiting (pid: 884)
[2019-06-13 15:48:36 +0800] [329] [CRITICAL] WORKER TIMEOUT (pid:877)
[2019-06-13 15:48:36 +0800] [329] [CRITICAL] WORKER TIMEOUT (pid:879)
[2019-06-13 15:48:36 +0800] [329] [CRITICAL] WORKER TIMEOUT (pid:880)
[2019-06-13 15:48:36 +0800] [329] [CRITICAL] WORKER TIMEOUT (pid:884)
[2019-06-13 15:48:36 +0800] [922] [INFO] Booting worker with pid: 922
[2019-06-13 15:48:36 +0800] [923] [INFO] Booting worker with pid: 923
[2019-06-13 15:48:36 +0800] [924] [INFO] Booting worker with pid: 924
[2019-06-13 15:48:36 +0800] [926] [INFO] Booting worker with pid: 926
[2019-06-13 15:48:36 +0800] [922] [ERROR] Exception in worker process
Traceback (most recent call last):
  File "/home/cl811/tools/miniconda3/envs/myenv/lib/python3.6/site-packages/gunicorn/arbiter.py", line 583, in spawn_worker
    worker.init_process()
  File "/home/cl811/tools/miniconda3/envs/myenv/lib/python3.6/site-packages/gunicorn/workers/ggevent.py", line 203, in init_process
    super(GeventWorker, self).init_process()
  File "/home/cl811/tools/miniconda3/envs/myenv/lib/python3.6/site-packages/gunicorn/workers/base.py", line 129, in init_process
    self.load_wsgi()
  File "/home/cl811/tools/miniconda3/envs/myenv/lib/python3.6/site-packages/gunicorn/workers/base.py", line 138, in load_wsgi
    self.wsgi = self.app.wsgi()
  File "/home/cl811/tools/miniconda3/envs/myenv/lib/python3.6/site-packages/gunicorn/app/base.py", line 67, in wsgi
    self.callable = self.load()
  File "/home/cl811/tools/miniconda3/envs/myenv/lib/python3.6/site-packages/gunicorn/app/wsgiapp.py", line 52, in load
    return self.load_wsgiapp()
  File "/home/cl811/tools/miniconda3/envs/myenv/lib/python3.6/site-packages/gunicorn/app/wsgiapp.py", line 41, in load_wsgiapp
    return util.import_app(self.app_uri)
  File "/home/cl811/tools/miniconda3/envs/myenv/lib/python3.6/site-packages/gunicorn/util.py", line 350, in import_app
    __import__(module)
  File "/home/cl811/work/19spring-courses/wsm/proj/ZDBK/run.py", line 3, in <module>
    app.run()
  File "/home/cl811/tools/miniconda3/envs/myenv/lib/python3.6/site-packages/flask/app.py", line 944, in run
    run_simple(host, port, self, **options)
  File "/home/cl811/tools/miniconda3/envs/myenv/lib/python3.6/site-packages/werkzeug/serving.py", line 987, in run_simple
    s.bind(server_address)
OSError: [Errno 98] Address already in use
[2019-06-13 15:48:36 +0800] [922] [INFO] Worker exiting (pid: 922)
[2019-06-13 15:48:36 +0800] [923] [ERROR] Exception in worker process
Traceback (most recent call last):
  File "/home/cl811/tools/miniconda3/envs/myenv/lib/python3.6/site-packages/gunicorn/arbiter.py", line 583, in spawn_worker
    worker.init_process()
  File "/home/cl811/tools/miniconda3/envs/myenv/lib/python3.6/site-packages/gunicorn/workers/ggevent.py", line 203, in init_process
    super(GeventWorker, self).init_process()
  File "/home/cl811/tools/miniconda3/envs/myenv/lib/python3.6/site-packages/gunicorn/workers/base.py", line 129, in init_process
    self.load_wsgi()
  File "/home/cl811/tools/miniconda3/envs/myenv/lib/python3.6/site-packages/gunicorn/workers/base.py", line 138, in load_wsgi
    self.wsgi = self.app.wsgi()
  File "/home/cl811/tools/miniconda3/envs/myenv/lib/python3.6/site-packages/gunicorn/app/base.py", line 67, in wsgi
    self.callable = self.load()
  File "/home/cl811/tools/miniconda3/envs/myenv/lib/python3.6/site-packages/gunicorn/app/wsgiapp.py", line 52, in load
    return self.load_wsgiapp()
  File "/home/cl811/tools/miniconda3/envs/myenv/lib/python3.6/site-packages/gunicorn/app/wsgiapp.py", line 41, in load_wsgiapp
    return util.import_app(self.app_uri)
  File "/home/cl811/tools/miniconda3/envs/myenv/lib/python3.6/site-packages/gunicorn/util.py", line 350, in import_app
    __import__(module)
  File "/home/cl811/work/19spring-courses/wsm/proj/ZDBK/run.py", line 3, in <module>
    app.run()
  File "/home/cl811/tools/miniconda3/envs/myenv/lib/python3.6/site-packages/flask/app.py", line 944, in run
    run_simple(host, port, self, **options)
  File "/home/cl811/tools/miniconda3/envs/myenv/lib/python3.6/site-packages/werkzeug/serving.py", line 987, in run_simple
    s.bind(server_address)
OSError: [Errno 98] Address already in use
[2019-06-13 15:48:36 +0800] [923] [INFO] Worker exiting (pid: 923)
[2019-06-13 15:48:36 +0800] [924] [ERROR] Exception in worker process
Traceback (most recent call last):
  File "/home/cl811/tools/miniconda3/envs/myenv/lib/python3.6/site-packages/gunicorn/arbiter.py", line 583, in spawn_worker
    worker.init_process()
  File "/home/cl811/tools/miniconda3/envs/myenv/lib/python3.6/site-packages/gunicorn/workers/ggevent.py", line 203, in init_process
    super(GeventWorker, self).init_process()
  File "/home/cl811/tools/miniconda3/envs/myenv/lib/python3.6/site-packages/gunicorn/workers/base.py", line 129, in init_process
    self.load_wsgi()
  File "/home/cl811/tools/miniconda3/envs/myenv/lib/python3.6/site-packages/gunicorn/workers/base.py", line 138, in load_wsgi
    self.wsgi = self.app.wsgi()
  File "/home/cl811/tools/miniconda3/envs/myenv/lib/python3.6/site-packages/gunicorn/app/base.py", line 67, in wsgi
    self.callable = self.load()
  File "/home/cl811/tools/miniconda3/envs/myenv/lib/python3.6/site-packages/gunicorn/app/wsgiapp.py", line 52, in load
    return self.load_wsgiapp()
  File "/home/cl811/tools/miniconda3/envs/myenv/lib/python3.6/site-packages/gunicorn/app/wsgiapp.py", line 41, in load_wsgiapp
    return util.import_app(self.app_uri)
  File "/home/cl811/tools/miniconda3/envs/myenv/lib/python3.6/site-packages/gunicorn/util.py", line 350, in import_app
    __import__(module)
  File "/home/cl811/work/19spring-courses/wsm/proj/ZDBK/run.py", line 3, in <module>
    app.run()
  File "/home/cl811/tools/miniconda3/envs/myenv/lib/python3.6/site-packages/flask/app.py", line 944, in run
    run_simple(host, port, self, **options)
  File "/home/cl811/tools/miniconda3/envs/myenv/lib/python3.6/site-packages/werkzeug/serving.py", line 987, in run_simple
    s.bind(server_address)
OSError: [Errno 98] Address already in use
[2019-06-13 15:48:36 +0800] [924] [INFO] Worker exiting (pid: 924)
[2019-06-13 15:48:36 +0800] [926] [ERROR] Exception in worker process
Traceback (most recent call last):
  File "/home/cl811/tools/miniconda3/envs/myenv/lib/python3.6/site-packages/gunicorn/arbiter.py", line 583, in spawn_worker
    worker.init_process()
  File "/home/cl811/tools/miniconda3/envs/myenv/lib/python3.6/site-packages/gunicorn/workers/ggevent.py", line 203, in init_process
    super(GeventWorker, self).init_process()
  File "/home/cl811/tools/miniconda3/envs/myenv/lib/python3.6/site-packages/gunicorn/workers/base.py", line 129, in init_process
    self.load_wsgi()
  File "/home/cl811/tools/miniconda3/envs/myenv/lib/python3.6/site-packages/gunicorn/workers/base.py", line 138, in load_wsgi
    self.wsgi = self.app.wsgi()
  File "/home/cl811/tools/miniconda3/envs/myenv/lib/python3.6/site-packages/gunicorn/app/base.py", line 67, in wsgi
    self.callable = self.load()
  File "/home/cl811/tools/miniconda3/envs/myenv/lib/python3.6/site-packages/gunicorn/app/wsgiapp.py", line 52, in load
    return self.load_wsgiapp()
  File "/home/cl811/tools/miniconda3/envs/myenv/lib/python3.6/site-packages/gunicorn/app/wsgiapp.py", line 41, in load_wsgiapp
    return util.import_app(self.app_uri)
  File "/home/cl811/tools/miniconda3/envs/myenv/lib/python3.6/site-packages/gunicorn/util.py", line 350, in import_app
    __import__(module)
  File "/home/cl811/work/19spring-courses/wsm/proj/ZDBK/run.py", line 3, in <module>
    app.run()
  File "/home/cl811/tools/miniconda3/envs/myenv/lib/python3.6/site-packages/flask/app.py", line 944, in run
    run_simple(host, port, self, **options)
  File "/home/cl811/tools/miniconda3/envs/myenv/lib/python3.6/site-packages/werkzeug/serving.py", line 987, in run_simple
    s.bind(server_address)
OSError: [Errno 98] Address already in use
[2019-06-13 15:48:36 +0800] [926] [INFO] Worker exiting (pid: 926)
[2019-06-13 15:48:47 +0800] [329] [INFO] Handling signal: term
[2019-06-13 15:48:47 +0800] [329] [INFO] Shutting down: Master
[2019-06-13 15:49:35 +0800] [1030] [DEBUG] Current configuration:
  config: config.py
  bind: ['127.0.0.1:5000']
  backlog: 2048
  workers: 4
  worker_class: gevent
  threads: 1
  worker_connections: 1000
  max_requests: 0
  max_requests_jitter: 0
  timeout: 30
  graceful_timeout: 30
  keepalive: 2
  limit_request_line: 4094
  limit_request_fields: 100
  limit_request_field_size: 8190
  reload: False
  reload_engine: auto
  reload_extra_files: []
  spew: False
  check_config: False
  preload_app: False
  sendfile: None
  reuse_port: False
  chdir: /home/cl811/work/19spring-courses/wsm/proj/ZDBK
  daemon: False
  raw_env: []
  pidfile: log/gunicorn.pid
  worker_tmp_dir: None
  user: 1000
  group: 1000
  umask: 0
  initgroups: False
  tmp_upload_dir: None
  secure_scheme_headers: {'X-FORWARDED-PROTOCOL': 'ssl', 'X-FORWARDED-PROTO': 'https', 'X-FORWARDED-SSL': 'on'}
  forwarded_allow_ips: ['127.0.0.1']
  accesslog: log/access.log
  disable_redirect_access_to_syslog: False
  access_log_format: %(h)s %(l)s %(u)s %(t)s "%(r)s" %(s)s %(b)s "%(f)s" "%(a)s"
  errorlog: log/debug.log
  loglevel: debug
  capture_output: False
  logger_class: gunicorn.glogging.Logger
  logconfig: None
  logconfig_dict: {}
  syslog_addr: udp://localhost:514
  syslog: False
  syslog_prefix: None
  syslog_facility: user
  enable_stdio_inheritance: False
  statsd_host: None
  statsd_prefix: 
  proc_name: None
  default_proc_name: run:app
  pythonpath: None
  paste: None
  on_starting: <function OnStarting.on_starting at 0x7fca6199c378>
  on_reload: <function OnReload.on_reload at 0x7fca6199c488>
  when_ready: <function WhenReady.when_ready at 0x7fca6199c598>
  pre_fork: <function Prefork.pre_fork at 0x7fca6199c6a8>
  post_fork: <function Postfork.post_fork at 0x7fca6199c7b8>
  post_worker_init: <function PostWorkerInit.post_worker_init at 0x7fca6199c8c8>
  worker_int: <function WorkerInt.worker_int at 0x7fca6199c9d8>
  worker_abort: <function WorkerAbort.worker_abort at 0x7fca6199cae8>
  pre_exec: <function PreExec.pre_exec at 0x7fca6199cbf8>
  pre_request: <function PreRequest.pre_request at 0x7fca6199cd08>
  post_request: <function PostRequest.post_request at 0x7fca6199cd90>
  child_exit: <function ChildExit.child_exit at 0x7fca6199cea0>
  worker_exit: <function WorkerExit.worker_exit at 0x7fca619ba048>
  nworkers_changed: <function NumWorkersChanged.nworkers_changed at 0x7fca619ba158>
  on_exit: <function OnExit.on_exit at 0x7fca619ba268>
  proxy_protocol: False
  proxy_allow_ips: ['127.0.0.1']
  keyfile: None
  certfile: None
  ssl_version: 2
  cert_reqs: 0
  ca_certs: None
  suppress_ragged_eofs: True
  do_handshake_on_connect: False
  ciphers: TLSv1
  raw_paste_global_conf: []
[2019-06-13 15:49:35 +0800] [1030] [INFO] Starting gunicorn 19.9.0
[2019-06-13 15:49:35 +0800] [1030] [DEBUG] Arbiter booted
[2019-06-13 15:49:35 +0800] [1030] [INFO] Listening at: http://127.0.0.1:5000 (1030)
[2019-06-13 15:49:35 +0800] [1030] [INFO] Using worker: gevent
[2019-06-13 15:49:35 +0800] [1033] [INFO] Booting worker with pid: 1033
[2019-06-13 15:49:35 +0800] [1035] [INFO] Booting worker with pid: 1035
[2019-06-13 15:49:35 +0800] [1036] [INFO] Booting worker with pid: 1036
[2019-06-13 15:49:35 +0800] [1038] [INFO] Booting worker with pid: 1038
[2019-06-13 15:49:35 +0800] [1030] [DEBUG] 4 workers
[2019-06-13 15:49:35 +0800] [1033] [ERROR] Exception in worker process
Traceback (most recent call last):
  File "/home/cl811/tools/miniconda3/envs/myenv/lib/python3.6/site-packages/gunicorn/arbiter.py", line 583, in spawn_worker
    worker.init_process()
  File "/home/cl811/tools/miniconda3/envs/myenv/lib/python3.6/site-packages/gunicorn/workers/ggevent.py", line 203, in init_process
    super(GeventWorker, self).init_process()
  File "/home/cl811/tools/miniconda3/envs/myenv/lib/python3.6/site-packages/gunicorn/workers/base.py", line 129, in init_process
    self.load_wsgi()
  File "/home/cl811/tools/miniconda3/envs/myenv/lib/python3.6/site-packages/gunicorn/workers/base.py", line 138, in load_wsgi
    self.wsgi = self.app.wsgi()
  File "/home/cl811/tools/miniconda3/envs/myenv/lib/python3.6/site-packages/gunicorn/app/base.py", line 67, in wsgi
    self.callable = self.load()
  File "/home/cl811/tools/miniconda3/envs/myenv/lib/python3.6/site-packages/gunicorn/app/wsgiapp.py", line 52, in load
    return self.load_wsgiapp()
  File "/home/cl811/tools/miniconda3/envs/myenv/lib/python3.6/site-packages/gunicorn/app/wsgiapp.py", line 41, in load_wsgiapp
    return util.import_app(self.app_uri)
  File "/home/cl811/tools/miniconda3/envs/myenv/lib/python3.6/site-packages/gunicorn/util.py", line 350, in import_app
    __import__(module)
  File "/home/cl811/work/19spring-courses/wsm/proj/ZDBK/run.py", line 3, in <module>
    app.run()
  File "/home/cl811/tools/miniconda3/envs/myenv/lib/python3.6/site-packages/flask/app.py", line 944, in run
    run_simple(host, port, self, **options)
  File "/home/cl811/tools/miniconda3/envs/myenv/lib/python3.6/site-packages/werkzeug/serving.py", line 987, in run_simple
    s.bind(server_address)
OSError: [Errno 98] Address already in use
[2019-06-13 15:49:35 +0800] [1033] [INFO] Worker exiting (pid: 1033)
[2019-06-13 15:49:35 +0800] [1035] [ERROR] Exception in worker process
Traceback (most recent call last):
  File "/home/cl811/tools/miniconda3/envs/myenv/lib/python3.6/site-packages/gunicorn/arbiter.py", line 583, in spawn_worker
    worker.init_process()
  File "/home/cl811/tools/miniconda3/envs/myenv/lib/python3.6/site-packages/gunicorn/workers/ggevent.py", line 203, in init_process
    super(GeventWorker, self).init_process()
  File "/home/cl811/tools/miniconda3/envs/myenv/lib/python3.6/site-packages/gunicorn/workers/base.py", line 129, in init_process
    self.load_wsgi()
  File "/home/cl811/tools/miniconda3/envs/myenv/lib/python3.6/site-packages/gunicorn/workers/base.py", line 138, in load_wsgi
    self.wsgi = self.app.wsgi()
  File "/home/cl811/tools/miniconda3/envs/myenv/lib/python3.6/site-packages/gunicorn/app/base.py", line 67, in wsgi
    self.callable = self.load()
  File "/home/cl811/tools/miniconda3/envs/myenv/lib/python3.6/site-packages/gunicorn/app/wsgiapp.py", line 52, in load
    return self.load_wsgiapp()
  File "/home/cl811/tools/miniconda3/envs/myenv/lib/python3.6/site-packages/gunicorn/app/wsgiapp.py", line 41, in load_wsgiapp
    return util.import_app(self.app_uri)
  File "/home/cl811/tools/miniconda3/envs/myenv/lib/python3.6/site-packages/gunicorn/util.py", line 350, in import_app
    __import__(module)
  File "/home/cl811/work/19spring-courses/wsm/proj/ZDBK/run.py", line 3, in <module>
    app.run()
  File "/home/cl811/tools/miniconda3/envs/myenv/lib/python3.6/site-packages/flask/app.py", line 944, in run
    run_simple(host, port, self, **options)
  File "/home/cl811/tools/miniconda3/envs/myenv/lib/python3.6/site-packages/werkzeug/serving.py", line 987, in run_simple
    s.bind(server_address)
OSError: [Errno 98] Address already in use
[2019-06-13 15:49:35 +0800] [1035] [INFO] Worker exiting (pid: 1035)
[2019-06-13 15:49:35 +0800] [1036] [ERROR] Exception in worker process
Traceback (most recent call last):
  File "/home/cl811/tools/miniconda3/envs/myenv/lib/python3.6/site-packages/gunicorn/arbiter.py", line 583, in spawn_worker
    worker.init_process()
  File "/home/cl811/tools/miniconda3/envs/myenv/lib/python3.6/site-packages/gunicorn/workers/ggevent.py", line 203, in init_process
    super(GeventWorker, self).init_process()
  File "/home/cl811/tools/miniconda3/envs/myenv/lib/python3.6/site-packages/gunicorn/workers/base.py", line 129, in init_process
    self.load_wsgi()
  File "/home/cl811/tools/miniconda3/envs/myenv/lib/python3.6/site-packages/gunicorn/workers/base.py", line 138, in load_wsgi
    self.wsgi = self.app.wsgi()
  File "/home/cl811/tools/miniconda3/envs/myenv/lib/python3.6/site-packages/gunicorn/app/base.py", line 67, in wsgi
    self.callable = self.load()
  File "/home/cl811/tools/miniconda3/envs/myenv/lib/python3.6/site-packages/gunicorn/app/wsgiapp.py", line 52, in load
    return self.load_wsgiapp()
  File "/home/cl811/tools/miniconda3/envs/myenv/lib/python3.6/site-packages/gunicorn/app/wsgiapp.py", line 41, in load_wsgiapp
    return util.import_app(self.app_uri)
  File "/home/cl811/tools/miniconda3/envs/myenv/lib/python3.6/site-packages/gunicorn/util.py", line 350, in import_app
    __import__(module)
  File "/home/cl811/work/19spring-courses/wsm/proj/ZDBK/run.py", line 3, in <module>
    app.run()
  File "/home/cl811/tools/miniconda3/envs/myenv/lib/python3.6/site-packages/flask/app.py", line 944, in run
    run_simple(host, port, self, **options)
  File "/home/cl811/tools/miniconda3/envs/myenv/lib/python3.6/site-packages/werkzeug/serving.py", line 987, in run_simple
    s.bind(server_address)
OSError: [Errno 98] Address already in use
[2019-06-13 15:49:35 +0800] [1036] [INFO] Worker exiting (pid: 1036)
[2019-06-13 15:49:35 +0800] [1038] [ERROR] Exception in worker process
Traceback (most recent call last):
  File "/home/cl811/tools/miniconda3/envs/myenv/lib/python3.6/site-packages/gunicorn/arbiter.py", line 583, in spawn_worker
    worker.init_process()
  File "/home/cl811/tools/miniconda3/envs/myenv/lib/python3.6/site-packages/gunicorn/workers/ggevent.py", line 203, in init_process
    super(GeventWorker, self).init_process()
  File "/home/cl811/tools/miniconda3/envs/myenv/lib/python3.6/site-packages/gunicorn/workers/base.py", line 129, in init_process
    self.load_wsgi()
  File "/home/cl811/tools/miniconda3/envs/myenv/lib/python3.6/site-packages/gunicorn/workers/base.py", line 138, in load_wsgi
    self.wsgi = self.app.wsgi()
  File "/home/cl811/tools/miniconda3/envs/myenv/lib/python3.6/site-packages/gunicorn/app/base.py", line 67, in wsgi
    self.callable = self.load()
  File "/home/cl811/tools/miniconda3/envs/myenv/lib/python3.6/site-packages/gunicorn/app/wsgiapp.py", line 52, in load
    return self.load_wsgiapp()
  File "/home/cl811/tools/miniconda3/envs/myenv/lib/python3.6/site-packages/gunicorn/app/wsgiapp.py", line 41, in load_wsgiapp
    return util.import_app(self.app_uri)
  File "/home/cl811/tools/miniconda3/envs/myenv/lib/python3.6/site-packages/gunicorn/util.py", line 350, in import_app
    __import__(module)
  File "/home/cl811/work/19spring-courses/wsm/proj/ZDBK/run.py", line 3, in <module>
    app.run()
  File "/home/cl811/tools/miniconda3/envs/myenv/lib/python3.6/site-packages/flask/app.py", line 944, in run
    run_simple(host, port, self, **options)
  File "/home/cl811/tools/miniconda3/envs/myenv/lib/python3.6/site-packages/werkzeug/serving.py", line 987, in run_simple
    s.bind(server_address)
OSError: [Errno 98] Address already in use
[2019-06-13 15:49:35 +0800] [1038] [INFO] Worker exiting (pid: 1038)
[2019-06-13 15:49:46 +0800] [1030] [INFO] Handling signal: winch
[2019-06-13 15:49:46 +0800] [1030] [DEBUG] SIGWINCH ignored. Not daemonized
[2019-06-13 15:49:57 +0800] [1030] [INFO] Handling signal: int
[2019-06-13 15:49:57 +0800] [1030] [INFO] Shutting down: Master
[2019-06-13 15:49:59 +0800] [1107] [DEBUG] Current configuration:
  config: config.py
  bind: ['127.0.0.1:5000']
  backlog: 2048
  workers: 4
  worker_class: gevent
  threads: 1
  worker_connections: 1000
  max_requests: 0
  max_requests_jitter: 0
  timeout: 30
  graceful_timeout: 30
  keepalive: 2
  limit_request_line: 4094
  limit_request_fields: 100
  limit_request_field_size: 8190
  reload: False
  reload_engine: auto
  reload_extra_files: []
  spew: False
  check_config: False
  preload_app: False
  sendfile: None
  reuse_port: False
  chdir: /home/cl811/work/19spring-courses/wsm/proj/ZDBK
  daemon: False
  raw_env: []
  pidfile: log/gunicorn.pid
  worker_tmp_dir: None
  user: 1000
  group: 1000
  umask: 0
  initgroups: False
  tmp_upload_dir: None
  secure_scheme_headers: {'X-FORWARDED-PROTOCOL': 'ssl', 'X-FORWARDED-PROTO': 'https', 'X-FORWARDED-SSL': 'on'}
  forwarded_allow_ips: ['127.0.0.1']
  accesslog: log/access.log
  disable_redirect_access_to_syslog: False
  access_log_format: %(h)s %(l)s %(u)s %(t)s "%(r)s" %(s)s %(b)s "%(f)s" "%(a)s"
  errorlog: log/debug.log
  loglevel: debug
  capture_output: False
  logger_class: gunicorn.glogging.Logger
  logconfig: None
  logconfig_dict: {}
  syslog_addr: udp://localhost:514
  syslog: False
  syslog_prefix: None
  syslog_facility: user
  enable_stdio_inheritance: False
  statsd_host: None
  statsd_prefix: 
  proc_name: None
  default_proc_name: run:app
  pythonpath: None
  paste: None
  on_starting: <function OnStarting.on_starting at 0x7f2c7746b378>
  on_reload: <function OnReload.on_reload at 0x7f2c7746b488>
  when_ready: <function WhenReady.when_ready at 0x7f2c7746b598>
  pre_fork: <function Prefork.pre_fork at 0x7f2c7746b6a8>
  post_fork: <function Postfork.post_fork at 0x7f2c7746b7b8>
  post_worker_init: <function PostWorkerInit.post_worker_init at 0x7f2c7746b8c8>
  worker_int: <function WorkerInt.worker_int at 0x7f2c7746b9d8>
  worker_abort: <function WorkerAbort.worker_abort at 0x7f2c7746bae8>
  pre_exec: <function PreExec.pre_exec at 0x7f2c7746bbf8>
  pre_request: <function PreRequest.pre_request at 0x7f2c7746bd08>
  post_request: <function PostRequest.post_request at 0x7f2c7746bd90>
  child_exit: <function ChildExit.child_exit at 0x7f2c7746bea0>
  worker_exit: <function WorkerExit.worker_exit at 0x7f2c77489048>
  nworkers_changed: <function NumWorkersChanged.nworkers_changed at 0x7f2c77489158>
  on_exit: <function OnExit.on_exit at 0x7f2c77489268>
  proxy_protocol: False
  proxy_allow_ips: ['127.0.0.1']
  keyfile: None
  certfile: None
  ssl_version: 2
  cert_reqs: 0
  ca_certs: None
  suppress_ragged_eofs: True
  do_handshake_on_connect: False
  ciphers: TLSv1
  raw_paste_global_conf: []
[2019-06-13 15:49:59 +0800] [1107] [INFO] Starting gunicorn 19.9.0
[2019-06-13 15:49:59 +0800] [1107] [DEBUG] Arbiter booted
[2019-06-13 15:49:59 +0800] [1107] [INFO] Listening at: http://127.0.0.1:5000 (1107)
[2019-06-13 15:49:59 +0800] [1107] [INFO] Using worker: gevent
[2019-06-13 15:49:59 +0800] [1110] [INFO] Booting worker with pid: 1110
[2019-06-13 15:49:59 +0800] [1111] [INFO] Booting worker with pid: 1111
[2019-06-13 15:50:00 +0800] [1114] [INFO] Booting worker with pid: 1114
[2019-06-13 15:50:00 +0800] [1115] [INFO] Booting worker with pid: 1115
[2019-06-13 15:50:00 +0800] [1107] [DEBUG] 4 workers
[2019-06-13 15:50:00 +0800] [1110] [ERROR] Exception in worker process
Traceback (most recent call last):
  File "/home/cl811/tools/miniconda3/envs/myenv/lib/python3.6/site-packages/gunicorn/arbiter.py", line 583, in spawn_worker
    worker.init_process()
  File "/home/cl811/tools/miniconda3/envs/myenv/lib/python3.6/site-packages/gunicorn/workers/ggevent.py", line 203, in init_process
    super(GeventWorker, self).init_process()
  File "/home/cl811/tools/miniconda3/envs/myenv/lib/python3.6/site-packages/gunicorn/workers/base.py", line 129, in init_process
    self.load_wsgi()
  File "/home/cl811/tools/miniconda3/envs/myenv/lib/python3.6/site-packages/gunicorn/workers/base.py", line 138, in load_wsgi
    self.wsgi = self.app.wsgi()
  File "/home/cl811/tools/miniconda3/envs/myenv/lib/python3.6/site-packages/gunicorn/app/base.py", line 67, in wsgi
    self.callable = self.load()
  File "/home/cl811/tools/miniconda3/envs/myenv/lib/python3.6/site-packages/gunicorn/app/wsgiapp.py", line 52, in load
    return self.load_wsgiapp()
  File "/home/cl811/tools/miniconda3/envs/myenv/lib/python3.6/site-packages/gunicorn/app/wsgiapp.py", line 41, in load_wsgiapp
    return util.import_app(self.app_uri)
  File "/home/cl811/tools/miniconda3/envs/myenv/lib/python3.6/site-packages/gunicorn/util.py", line 350, in import_app
    __import__(module)
  File "/home/cl811/work/19spring-courses/wsm/proj/ZDBK/run.py", line 3, in <module>
    app.run()
  File "/home/cl811/tools/miniconda3/envs/myenv/lib/python3.6/site-packages/flask/app.py", line 944, in run
    run_simple(host, port, self, **options)
  File "/home/cl811/tools/miniconda3/envs/myenv/lib/python3.6/site-packages/werkzeug/serving.py", line 987, in run_simple
    s.bind(server_address)
OSError: [Errno 98] Address already in use
[2019-06-13 15:50:00 +0800] [1110] [INFO] Worker exiting (pid: 1110)
[2019-06-13 15:50:00 +0800] [1111] [ERROR] Exception in worker process
Traceback (most recent call last):
  File "/home/cl811/tools/miniconda3/envs/myenv/lib/python3.6/site-packages/gunicorn/arbiter.py", line 583, in spawn_worker
    worker.init_process()
  File "/home/cl811/tools/miniconda3/envs/myenv/lib/python3.6/site-packages/gunicorn/workers/ggevent.py", line 203, in init_process
    super(GeventWorker, self).init_process()
  File "/home/cl811/tools/miniconda3/envs/myenv/lib/python3.6/site-packages/gunicorn/workers/base.py", line 129, in init_process
    self.load_wsgi()
  File "/home/cl811/tools/miniconda3/envs/myenv/lib/python3.6/site-packages/gunicorn/workers/base.py", line 138, in load_wsgi
    self.wsgi = self.app.wsgi()
  File "/home/cl811/tools/miniconda3/envs/myenv/lib/python3.6/site-packages/gunicorn/app/base.py", line 67, in wsgi
    self.callable = self.load()
  File "/home/cl811/tools/miniconda3/envs/myenv/lib/python3.6/site-packages/gunicorn/app/wsgiapp.py", line 52, in load
    return self.load_wsgiapp()
  File "/home/cl811/tools/miniconda3/envs/myenv/lib/python3.6/site-packages/gunicorn/app/wsgiapp.py", line 41, in load_wsgiapp
    return util.import_app(self.app_uri)
  File "/home/cl811/tools/miniconda3/envs/myenv/lib/python3.6/site-packages/gunicorn/util.py", line 350, in import_app
    __import__(module)
  File "/home/cl811/work/19spring-courses/wsm/proj/ZDBK/run.py", line 3, in <module>
    app.run()
  File "/home/cl811/tools/miniconda3/envs/myenv/lib/python3.6/site-packages/flask/app.py", line 944, in run
    run_simple(host, port, self, **options)
  File "/home/cl811/tools/miniconda3/envs/myenv/lib/python3.6/site-packages/werkzeug/serving.py", line 987, in run_simple
    s.bind(server_address)
OSError: [Errno 98] Address already in use
[2019-06-13 15:50:00 +0800] [1111] [INFO] Worker exiting (pid: 1111)
[2019-06-13 15:50:00 +0800] [1114] [ERROR] Exception in worker process
Traceback (most recent call last):
  File "/home/cl811/tools/miniconda3/envs/myenv/lib/python3.6/site-packages/gunicorn/arbiter.py", line 583, in spawn_worker
    worker.init_process()
  File "/home/cl811/tools/miniconda3/envs/myenv/lib/python3.6/site-packages/gunicorn/workers/ggevent.py", line 203, in init_process
    super(GeventWorker, self).init_process()
  File "/home/cl811/tools/miniconda3/envs/myenv/lib/python3.6/site-packages/gunicorn/workers/base.py", line 129, in init_process
    self.load_wsgi()
  File "/home/cl811/tools/miniconda3/envs/myenv/lib/python3.6/site-packages/gunicorn/workers/base.py", line 138, in load_wsgi
    self.wsgi = self.app.wsgi()
  File "/home/cl811/tools/miniconda3/envs/myenv/lib/python3.6/site-packages/gunicorn/app/base.py", line 67, in wsgi
    self.callable = self.load()
  File "/home/cl811/tools/miniconda3/envs/myenv/lib/python3.6/site-packages/gunicorn/app/wsgiapp.py", line 52, in load
    return self.load_wsgiapp()
  File "/home/cl811/tools/miniconda3/envs/myenv/lib/python3.6/site-packages/gunicorn/app/wsgiapp.py", line 41, in load_wsgiapp
    return util.import_app(self.app_uri)
  File "/home/cl811/tools/miniconda3/envs/myenv/lib/python3.6/site-packages/gunicorn/util.py", line 350, in import_app
    __import__(module)
  File "/home/cl811/work/19spring-courses/wsm/proj/ZDBK/run.py", line 3, in <module>
    app.run()
  File "/home/cl811/tools/miniconda3/envs/myenv/lib/python3.6/site-packages/flask/app.py", line 944, in run
    run_simple(host, port, self, **options)
  File "/home/cl811/tools/miniconda3/envs/myenv/lib/python3.6/site-packages/werkzeug/serving.py", line 987, in run_simple
    s.bind(server_address)
OSError: [Errno 98] Address already in use
[2019-06-13 15:50:00 +0800] [1114] [INFO] Worker exiting (pid: 1114)
[2019-06-13 15:50:00 +0800] [1115] [ERROR] Exception in worker process
Traceback (most recent call last):
  File "/home/cl811/tools/miniconda3/envs/myenv/lib/python3.6/site-packages/gunicorn/arbiter.py", line 583, in spawn_worker
    worker.init_process()
  File "/home/cl811/tools/miniconda3/envs/myenv/lib/python3.6/site-packages/gunicorn/workers/ggevent.py", line 203, in init_process
    super(GeventWorker, self).init_process()
  File "/home/cl811/tools/miniconda3/envs/myenv/lib/python3.6/site-packages/gunicorn/workers/base.py", line 129, in init_process
    self.load_wsgi()
  File "/home/cl811/tools/miniconda3/envs/myenv/lib/python3.6/site-packages/gunicorn/workers/base.py", line 138, in load_wsgi
    self.wsgi = self.app.wsgi()
  File "/home/cl811/tools/miniconda3/envs/myenv/lib/python3.6/site-packages/gunicorn/app/base.py", line 67, in wsgi
    self.callable = self.load()
  File "/home/cl811/tools/miniconda3/envs/myenv/lib/python3.6/site-packages/gunicorn/app/wsgiapp.py", line 52, in load
    return self.load_wsgiapp()
  File "/home/cl811/tools/miniconda3/envs/myenv/lib/python3.6/site-packages/gunicorn/app/wsgiapp.py", line 41, in load_wsgiapp
    return util.import_app(self.app_uri)
  File "/home/cl811/tools/miniconda3/envs/myenv/lib/python3.6/site-packages/gunicorn/util.py", line 350, in import_app
    __import__(module)
  File "/home/cl811/work/19spring-courses/wsm/proj/ZDBK/run.py", line 3, in <module>
    app.run()
  File "/home/cl811/tools/miniconda3/envs/myenv/lib/python3.6/site-packages/flask/app.py", line 944, in run
    run_simple(host, port, self, **options)
  File "/home/cl811/tools/miniconda3/envs/myenv/lib/python3.6/site-packages/werkzeug/serving.py", line 987, in run_simple
    s.bind(server_address)
OSError: [Errno 98] Address already in use
[2019-06-13 15:50:00 +0800] [1115] [INFO] Worker exiting (pid: 1115)
[2019-06-13 15:50:21 +0800] [1107] [INFO] Handling signal: int
[2019-06-13 15:50:21 +0800] [1107] [INFO] Shutting down: Master
